Workbook

Sheet 변경(260104_260131)
A1: 근무표 변경시 파트장에게 확인받고 변경해주세요 확정된 근무표의 변경은 지양해주시길 바랍니다. 근무표 변경시 되도록 동일한 그룹내에서 변경해주세요
J3: 2026.01.04._26.01.31. | AB3: 간호사 38(파트장포함)
C5: 4 | D5: 5 | E5: 6 | F5: 7 | G5: 8 | H5: 9 | I5: 10 | J5: 11 | K5: 12 | L5: 13 | M5: 14 | N5: 15 | O5: 16 | P5: 17 | Q5: 18 | R5: 19 | S5: 20 | T5: 21 | U5: 22 | V5: 23 | W5: 24 | X5: 25 | Y5: 26 | Z5: 27 | AA5: 28 | AB5: 29 | AC5: 30 | AD5: 31 | AE5: 총 | AF5: 총 | AK5: 1 | AM5: 2 | AO5: 3 | AQ5: 4
B6: 비고 | C6: 일 | D6: 월 | E6: 화 | F6: 수 | G6: 목 | H6: 금 | I6: 토 | J6: 일 | K6: 월 | L6: 화 | M6: 수 | N6: 목 | O6: 금 | P6: 토 | Q6: 일 | R6: 월 | S6: 화 | T6: 수 | U6: 목 | V6: 금 | W6: 토 | X6: 일 | Y6: 월 | Z6: 화 | AA6: 수 | AB6: 목 | AC6: 금 | AD6: 토 | AE6: OFF | AF6: N | AK6: 주 | AL6: OFF | AM6: 주 | AN6: OFF | AO6: 주 | AP6: OFF | AQ6: 주 | AR6: OFF | AT6: 특휴 | AU6: 경가 | AV6: 병가 | AW6: 공 | AX6: 생휴 | AY6: 법휴 | AZ6: OFF | BA6: VAC | BB6: 출산 | BC6: 수면 | BD6: 주휴 | BE6: OFF계 | BF6: N | BG6: 병가,OFF,공휴 포함
A7: 이경희 | C7: D | D7: 주 | E7: D | F7: off | G7: D | H7: D | I7: D | J7: D | K7: 주 | L7: D | M7: E | N7: N | O7: OFF | P7: N | Q7: OFF | R7: 주 | S7: E | T7: E | U7: N | V7: VAC | W7: E | X7: E | Y7: 주 | Z7: D | AA7: N | AB7: OFF | AC7: 생휴 | AD7: VAC | AE7: =SUM(AT7:BD7) -> 11 | AF7: =COUNTIF(C7:AD7,"N") -> 4 | AK7: =COUNTIF($C7:$I7,AK$6) -> 1 | AL7: =COUNTIF($C7:$I7,AL$6&"*") -> 1 | AM7: =COUNTIF($J7:$P7,AM$6) -> 1 | AN7: =COUNTIF($J7:$P7,AN$6) -> 1 | AO7: =COUNTIF($Q7:$W7,AO$6) -> 1 | AP7: =COUNTIF($Q7:$W7,AP$6) -> 1 | AQ7: =COUNTIF($X7:$AD7,AQ$6) -> 1 | AR7: =COUNTIF($X7:$AD7,AR$6) -> 1 | AS7: 이경희 | AT7: =COUNTIF(C7:AD7,"특*") -> 0 | AU7: =COUNTIF(C7:AD7,"경가") -> 0 | AV7: =COUNTIF(C7:AD7,"병*") -> 0 | AW7: =COUNTIF(C7:AD7,"공*") -> 0 | AX7: =COUNTIF(C7:AD7,"생*")+COUNTIF(C7:AD7,"산전")+COUNTIF(C7:AD7,"검진") -> 1 | AY7: =COUNTIF(C7:AD7,"법*") -> 0 | AZ7: =COUNTIF(C7:AD7,"*OFF*") -> 4 | BA7: =COUNTIF(C7:AD7,"VAC*")+COUNTIF(C7:AD7,"휴가") -> 2 | BB7: =COUNTIF(B7:AC7,"출산*") -> 0 | BC7: =COUNTIF(C7:AD7,"*수면*") -> 0 | BD7: =COUNTIF(C7:AD7,"주") -> 4 | BE7: =SUM(AX7:BD7) -> 11 | BF7: =COUNTIF(J7:AD7,"N") -> 4 | BG7: =SUM(AU7:BD7) -> 11
A8: 오선영 | C8: N | D8: 휴가 | E8: 주 | F8: D | G8: OFF | H8: N | I8: N | J8: OFF | K8: 생휴 | L8: 주 | M8: D | N8: D | O8: 번표 | P8: D | Q8: D | R8: OFF | S8: 주 | T8: 휴가 | U8: D | V8: D | W8: D | X8: D | Y8: E | Z8: 주 | AA8: D | AB8: D | AC8: OFF | AD8: N | AE8: =SUM(AT8:BD8) -> 11 | AF8: =COUNTIF(C8:AD8,"N") -> 4 | AK8: =COUNTIF($C8:$I8,AK$6) -> 1 | AL8: =COUNTIF($C8:$I8,AL$6&"*") -> 1 | AM8: =COUNTIF($J8:$P8,AM$6) -> 1 | AN8: =COUNTIF($J8:$P8,AN$6) -> 1 | AO8: =COUNTIF($Q8:$W8,AO$6) -> 1 | AP8: =COUNTIF($Q8:$W8,AP$6) -> 1 | AQ8: =COUNTIF($X8:$AD8,AQ$6) -> 1 | AR8: =COUNTIF($X8:$AD8,AR$6) -> 1 | AS8: 오선영 | AT8: =COUNTIF(C8:AD8,"특*") -> 0 | AU8: =COUNTIF(C8:AD8,"경가") -> 0 | AV8: =COUNTIF(C8:AD8,"병*") -> 0 | AW8: =COUNTIF(C8:AD8,"공*") -> 0 | AX8: =COUNTIF(C8:AD8,"생*")+COUNTIF(C8:AD8,"산전")+COUNTIF(C8:AD8,"검진") -> 1 | AY8: =COUNTIF(C8:AD8,"법*") -> 0 | AZ8: =COUNTIF(C8:AD8,"*OFF*") -> 4 | BA8: =COUNTIF(C8:AD8,"VAC*")+COUNTIF(C8:AD8,"휴가") -> 2 | BB8: =COUNTIF(B8:AC8,"출산*") -> 0 | BC8: =COUNTIF(C8:AD8,"*수면*") -> 0 | BD8: =COUNTIF(C8:AD8,"주") -> 4 | BE8: =SUM(AX8:BD8) -> 11 | BF8: =COUNTIF(J8:AD8,"N") -> 1 | BG8: =SUM(AU8:BD8) -> 11
A9: 우영미 | C9: E | D9: E | E9: E | F9: E | G9: 주 | H9: OFF | I9: 수면12 | J9: E | K9: E | L9: N | M9: N | N9: 주 | O9: off | P9: E | Q9: E | R9: OFF | S9: N | T9: N | U9: 주 | V9: VAC | W9: 생휴 | X9: off | Y9: D | Z9: E | AA9: E | AB9: 주 | AC9: D | AD9: D | AE9: =SUM(AT9:BD9) -> 11 | AF9: =COUNTIF(C9:AD9,"N") -> 4 | AK9: =COUNTIF($C9:$I9,AK$6) -> 1 | AL9: =COUNTIF($C9:$I9,AL$6&"*") -> 1 | AM9: =COUNTIF($J9:$P9,AM$6) -> 1 | AN9: =COUNTIF($J9:$P9,AN$6) -> 1 | AO9: =COUNTIF($Q9:$W9,AO$6) -> 1 | AP9: =COUNTIF($Q9:$W9,AP$6) -> 1 | AQ9: =COUNTIF($X9:$AD9,AQ$6) -> 1 | AR9: =COUNTIF($X9:$AD9,AR$6) -> 1 | AS9: 우영미 | AT9: =COUNTIF(C9:AD9,"특*") -> 0 | AU9: =COUNTIF(C9:AD9,"경가") -> 0 | AV9: =COUNTIF(C9:AD9,"병*") -> 0 | AW9: =COUNTIF(C9:AD9,"공*") -> 0 | AX9: =COUNTIF(C9:AD9,"생*")+COUNTIF(C9:AD9,"산전")+COUNTIF(C9:AD9,"검진") -> 1 | AY9: =COUNTIF(C9:AD9,"법*") -> 0 | AZ9: =COUNTIF(C9:AD9,"*OFF*") -> 4 | BA9: =COUNTIF(C9:AD9,"VAC*")+COUNTIF(C9:AD9,"휴가") -> 1 | BB9: =COUNTIF(B9:AC9,"출산*") -> 0 | BC9: =COUNTIF(C9:AD9,"*수면*") -> 1 | BD9: =COUNTIF(C9:AD9,"주") -> 4 | BE9: =SUM(AX9:BD9) -> 11 | BF9: =COUNTIF(J9:AD9,"N") -> 4 | BG9: =SUM(AU9:BD9) -> 11
A10: 전상배 | C10: VAC | D10: 주 | E10: D | F10: D | G10: D | H10: D | I10: OFF | J10: OFF | K10: 주 | L10: D | M10: D | N10: N | O10: N | P10: N | Q10: OFF | R10: 주 | S10: VAC | T10: D | U10: D | V10: N | W10: N | X10: N | Y10: 주 | Z10: OFF | AA10: D | AB10: D | AC10: D | AD10: 수면01 | AE10: =SUM(AT10:BD10) -> 11 | AF10: =COUNTIF(C10:AD10,"N") -> 6 | AK10: =COUNTIF($C10:$I10,AK$6) -> 1 | AL10: =COUNTIF($C10:$I10,AL$6&"*") -> 1 | AM10: =COUNTIF($J10:$P10,AM$6) -> 1 | AN10: =COUNTIF($J10:$P10,AN$6) -> 1 | AO10: =COUNTIF($Q10:$W10,AO$6) -> 1 | AP10: =COUNTIF($Q10:$W10,AP$6) -> 1 | AQ10: =COUNTIF($X10:$AD10,AQ$6) -> 1 | AR10: =COUNTIF($X10:$AD10,AR$6) -> 1 | AS10: 전상배 | AT10: =COUNTIF(C10:AD10,"특*") -> 0 | AU10: =COUNTIF(C10:AD10,"경가") -> 0 | AV10: =COUNTIF(C10:AD10,"병*") -> 0 | AW10: =COUNTIF(C10:AD10,"공*") -> 0 | AX10: =COUNTIF(C10:AD10,"생*")+COUNTIF(C10:AD10,"산전")+COUNTIF(C10:AD10,"검진") -> 0 | AY10: =COUNTIF(C10:AD10,"법*") -> 0 | AZ10: =COUNTIF(C10:AD10,"*OFF*") -> 4 | BA10: =COUNTIF(C10:AD10,"VAC*")+COUNTIF(C10:AD10,"휴가") -> 2 | BB10: =COUNTIF(B10:AC10,"출산*") -> 0 | BC10: =COUNTIF(C10:AD10,"*수면*") -> 1 | BD10: =COUNTIF(C10:AD10,"주") -> 4 | BE10: =SUM(AX10:BD10) -> 11 | BF10: =COUNTIF(J10:AD10,"N") -> 6 | BG10: =SUM(AU10:BD10) -> 11
A11: 안일심 | C11: 주 | D11: OFF | E11: 특휴 | F11: D | G11: D | H11: OFF | I11: 생휴 | J11: 주 | K11: OFF | L11: E | M11: OFF | N11: D | O11: D | P11: N | Q11: 주 | R11: E | S11: N | T11: OFF | U11: OFF | V11: N | W11: N | X11: 주 | Y11: OFF | Z11: E | AA11: E | AB11: OFF | AC11: N | AD11: N | AE11: =SUM(AT11:BD11) -> 14 | AF11: =COUNTIF(C11:AD11,"N") -> 6 | AK11: =COUNTIF($C11:$I11,AK$6) -> 1 | AL11: =COUNTIF($C11:$I11,AL$6&"*") -> 2 | AM11: =COUNTIF($J11:$P11,AM$6) -> 1 | AN11: =COUNTIF($J11:$P11,AN$6) -> 2 | AO11: =COUNTIF($Q11:$W11,AO$6) -> 1 | AP11: =COUNTIF($Q11:$W11,AP$6) -> 2 | AQ11: =COUNTIF($X11:$AD11,AQ$6) -> 1 | AR11: =COUNTIF($X11:$AD11,AR$6) -> 2 | AS11: 안일심 | AT11: =COUNTIF(C11:AD11,"특*") -> 1 | AU11: =COUNTIF(C11:AD11,"경가") -> 0 | AV11: =COUNTIF(C11:AD11,"병*") -> 0 | AW11: =COUNTIF(C11:AD11,"공*") -> 0 | AX11: =COUNTIF(C11:AD11,"생*")+COUNTIF(C11:AD11,"산전")+COUNTIF(C11:AD11,"검진") -> 1 | AY11: =COUNTIF(C11:AD11,"법*") -> 0 | AZ11: =COUNTIF(C11:AD11,"*OFF*") -> 8 | BA11: =COUNTIF(C11:AD11,"VAC*")+COUNTIF(C11:AD11,"휴가") -> 0 | BB11: =COUNTIF(B11:AC11,"출산*") -> 0 | BC11: =COUNTIF(C11:AD11,"*수면*") -> 0 | BD11: =COUNTIF(C11:AD11,"주") -> 4 | BE11: =SUM(AX11:BD11) -> 13 | BF11: =COUNTIF(J11:AD11,"N") -> 6 | BG11: =SUM(AU11:BD11) -> 13
A12: 조은애 | C12: 수면12 | D12: N | E12: N | F12: OFF | G12: OFF | H12: 주 | I12: D | J12: OFF | K12: D | L12: D | M12: OFF | N12: D | O12: 주 | P12: 생휴 | Q12: N | R12: N | S12: OFF | T12: OFF | U12: E | V12: 주 | W12: E | X12: E | Y12: OFF | Z12: N | AA12: N | AB12: off | AC12: 주 | AD12: D | AE12: =SUM(AT12:BD12) -> 14 | AF12: =COUNTIF(C12:AD12,"N") -> 6 | AK12: =COUNTIF($C12:$I12,AK$6) -> 1 | AL12: =COUNTIF($C12:$I12,AL$6&"*") -> 2 | AM12: =COUNTIF($J12:$P12,AM$6) -> 1 | AN12: =COUNTIF($J12:$P12,AN$6) -> 2 | AO12: =COUNTIF($Q12:$W12,AO$6) -> 1 | AP12: =COUNTIF($Q12:$W12,AP$6) -> 2 | AQ12: =COUNTIF($X12:$AD12,AQ$6) -> 1 | AR12: =COUNTIF($X12:$AD12,AR$6) -> 2 | AS12: 조은애 | AT12: =COUNTIF(C12:AD12,"특*") -> 0 | AU12: =COUNTIF(C12:AD12,"경가") -> 0 | AV12: =COUNTIF(C12:AD12,"병*") -> 0 | AW12: =COUNTIF(C12:AD12,"공*") -> 0 | AX12: =COUNTIF(C12:AD12,"생*")+COUNTIF(C12:AD12,"산전")+COUNTIF(C12:AD12,"검진") -> 1 | AY12: =COUNTIF(C12:AD12,"법*") -> 0 | AZ12: =COUNTIF(C12:AD12,"*OFF*") -> 8 | BA12: =COUNTIF(C12:AD12,"VAC*")+COUNTIF(C12:AD12,"휴가") -> 0 | BB12: =COUNTIF(B12:AC12,"출산*") -> 0 | BC12: =COUNTIF(C12:AD12,"*수면*") -> 1 | BD12: =COUNTIF(C12:AD12,"주") -> 4 | BE12: =SUM(AX12:BD12) -> 14 | BF12: =COUNTIF(J12:AD12,"N") -> 4 | BG12: =SUM(AU12:BD12) -> 14
A13: 우혜린 | C13: E | D13: OFF | E13: E | F13: N | G13: N | H13: N | I13: 주 | J13: OFF | K13: E | L13: E | M13: E | N13: E | O13: VAC | P13: 주 | Q13: OFF | R13: 생휴 | S13: D | T13: D | U13: N | V13: N | W13: 주 | X13: off | Y13: E | Z13: E | AA13: E | AB13: N | AC13: VAC | AD13: 주 | AE13: =SUM(AT13:BD13) -> 11 | AF13: =COUNTIF(C13:AD13,"N") -> 6 | AK13: =COUNTIF($C13:$I13,AK$6) -> 1 | AL13: =COUNTIF($C13:$I13,AL$6&"*") -> 1 | AM13: =COUNTIF($J13:$P13,AM$6) -> 1 | AN13: =COUNTIF($J13:$P13,AN$6) -> 1 | AO13: =COUNTIF($Q13:$W13,AO$6) -> 1 | AP13: =COUNTIF($Q13:$W13,AP$6) -> 1 | AQ13: =COUNTIF($X13:$AD13,AQ$6) -> 1 | AR13: =COUNTIF($X13:$AD13,AR$6) -> 1 | AS13: 우혜린 | AT13: =COUNTIF(C13:AD13,"특*") -> 0 | AU13: =COUNTIF(C13:AD13,"경가") -> 0 | AV13: =COUNTIF(C13:AD13,"병*") -> 0 | AW13: =COUNTIF(C13:AD13,"공*") -> 0 | AX13: =COUNTIF(C13:AD13,"생*")+COUNTIF(C13:AD13,"산전")+COUNTIF(C13:AD13,"검진") -> 1 | AY13: =COUNTIF(C13:AD13,"법*") -> 0 | AZ13: =COUNTIF(C13:AD13,"*OFF*") -> 4 | BA13: =COUNTIF(C13:AD13,"VAC*")+COUNTIF(C13:AD13,"휴가") -> 2 | BB13: =COUNTIF(B13:AC13,"출산*") -> 0 | BC13: =COUNTIF(C13:AD13,"*수면*") -> 0 | BD13: =COUNTIF(C13:AD13,"주") -> 4 | BE13: =SUM(AX13:BD13) -> 11 | BF13: =COUNTIF(J13:AD13,"N") -> 3 | BG13: =SUM(AU13:BD13) -> 11
A14: 유지연 | C14: D | D14: D | E14: D | F14: 주 | G14: off | H14: E | I14: E | J14: N | K14: N | L14: OFF | M14: 주 | N14: E | O14: E | P14: E | Q14: off | R14: 생휴 | S14: 수면12 | T14: 주 | U14: D | V14: VAC | W14: E | X14: N | Y14: N | Z14: N | AA14: 주 | AB14: OFF | AC14: E | AD14: E | AE14: =SUM(AT14:BD14) -> 11 | AF14: =COUNTIF(C14:AD14,"N") -> 5 | AK14: =COUNTIF($C14:$I14,AK$6) -> 1 | AL14: =COUNTIF($C14:$I14,AL$6&"*") -> 1 | AM14: =COUNTIF($J14:$P14,AM$6) -> 1 | AN14: =COUNTIF($J14:$P14,AN$6) -> 1 | AO14: =COUNTIF($Q14:$W14,AO$6) -> 1 | AP14: =COUNTIF($Q14:$W14,AP$6) -> 1 | AQ14: =COUNTIF($X14:$AD14,AQ$6) -> 1 | AR14: =COUNTIF($X14:$AD14,AR$6) -> 1 | AS14: 유지연 | AT14: =COUNTIF(C14:AD14,"특*") -> 0 | AU14: =COUNTIF(C14:AD14,"경가") -> 0 | AV14: =COUNTIF(C14:AD14,"병*") -> 0 | AW14: =COUNTIF(C14:AD14,"공*") -> 0 | AX14: =COUNTIF(C14:AD14,"생*")+COUNTIF(C14:AD14,"산전")+COUNTIF(C14:AD14,"검진") -> 1 | AY14: =COUNTIF(C14:AD14,"법*") -> 0 | AZ14: =COUNTIF(C14:AD14,"*OFF*") -> 4 | BA14: =COUNTIF(C14:AD14,"VAC*")+COUNTIF(C14:AD14,"휴가") -> 1 | BB14: =COUNTIF(B14:AC14,"출산*") -> 0 | BC14: =COUNTIF(C14:AD14,"*수면*") -> 1 | BD14: =COUNTIF(C14:AD14,"주") -> 4 | BE14: =SUM(AX14:BD14) -> 11 | BF14: =COUNTIF(J14:AD14,"N") -> 5 | BG14: =SUM(AU14:BD14) -> 11
A15: 서희정 | C15: N | D15: OFF | E15: VAC | F15: E | G15: E | H15: 생휴 | I15: 주 | J15: VAC | K15: OFF | L15: E | M15: N | N15: N | O15: N | P15: 주 | Q15: OFF | R15: D | S15: E | T15: E | U15: E | V15: E | W15: 주 | X15: E | Y15: N | Z15: OFF | AA15: E | AB15: E | AC15: N | AD15: 주 | AE15: =SUM(AT15:BD15) -> 11 | AF15: =COUNTIF(C15:AD15,"N") -> 6 | AK15: =COUNTIF($C15:$I15,AK$6) -> 1 | AL15: =COUNTIF($C15:$I15,AL$6&"*") -> 1 | AM15: =COUNTIF($J15:$P15,AM$6) -> 1 | AN15: =COUNTIF($J15:$P15,AN$6) -> 1 | AO15: =COUNTIF($Q15:$W15,AO$6) -> 1 | AP15: =COUNTIF($Q15:$W15,AP$6) -> 1 | AQ15: =COUNTIF($X15:$AD15,AQ$6) -> 1 | AR15: =COUNTIF($X15:$AD15,AR$6) -> 1 | AS15: 서희정 | AT15: =COUNTIF(C15:AD15,"특*") -> 0 | AU15: =COUNTIF(C15:AD15,"경가") -> 0 | AV15: =COUNTIF(C15:AD15,"병*") -> 0 | AW15: =COUNTIF(C15:AD15,"공*") -> 0 | AX15: =COUNTIF(C15:AD15,"생*")+COUNTIF(C15:AD15,"산전")+COUNTIF(C15:AD15,"검진") -> 1 | AY15: =COUNTIF(C15:AD15,"법*") -> 0 | AZ15: =COUNTIF(C15:AD15,"*OFF*") -> 4 | BA15: =COUNTIF(C15:AD15,"VAC*")+COUNTIF(C15:AD15,"휴가") -> 2 | BB15: =COUNTIF(B15:AC15,"출산*") -> 0 | BC15: =COUNTIF(C15:AD15,"*수면*") -> 0 | BD15: =COUNTIF(C15:AD15,"주") -> 4 | BE15: =SUM(AX15:BD15) -> 11 | BF15: =COUNTIF(J15:AD15,"N") -> 5 | BG15: =SUM(AU15:BD15) -> 11
A16: 김도연 | C16: 주 | D16: 중2 | E16: N | F16: N | G16: OFF | H16: OFF | I16: N | J16: 주 | K16: OFF | L16: OFF | M16: D | N16: D | O16: 중2 | P16: VAC | Q16: 주 | R16: E | S16: N | T16: OFF | U16: OFF | V16: 중2 | W16: D | X16: 주 | Y16: N | Z16: 생휴 | AA16: OFF | AB16: 중2 | AC16: OFF | AD16: E | AE16: =SUM(AT16:BD16) -> 14 | AF16: =COUNTIF(C16:AD16,"N") -> 5 | AK16: =COUNTIF($C16:$I16,AK$6) -> 1 | AL16: =COUNTIF($C16:$I16,AL$6&"*") -> 2 | AM16: =COUNTIF($J16:$P16,AM$6) -> 1 | AN16: =COUNTIF($J16:$P16,AN$6) -> 2 | AO16: =COUNTIF($Q16:$W16,AO$6) -> 1 | AP16: =COUNTIF($Q16:$W16,AP$6) -> 2 | AQ16: =COUNTIF($X16:$AD16,AQ$6) -> 1 | AR16: =COUNTIF($X16:$AD16,AR$6) -> 2 | AS16: 김도연 | AT16: =COUNTIF(C16:AD16,"특*") -> 0 | AU16: =COUNTIF(C16:AD16,"경가") -> 0 | AV16: =COUNTIF(C16:AD16,"병*") -> 0 | AW16: =COUNTIF(C16:AD16,"공*") -> 0 | AX16: =COUNTIF(C16:AD16,"생*")+COUNTIF(C16:AD16,"산전")+COUNTIF(C16:AD16,"검진") -> 1 | AY16: =COUNTIF(C16:AD16,"법*") -> 0 | AZ16: =COUNTIF(C16:AD16,"*OFF*") -> 8 | BA16: =COUNTIF(C16:AD16,"VAC*")+COUNTIF(C16:AD16,"휴가") -> 1 | BB16: =COUNTIF(B16:AC16,"출산*") -> 0 | BC16: =COUNTIF(C16:AD16,"*수면*") -> 0 | BD16: =COUNTIF(C16:AD16,"주") -> 4 | BE16: =SUM(AX16:BD16) -> 14 | BF16: =COUNTIF(J16:AD16,"N") -> 2 | BG16: =SUM(AU16:BD16) -> 14
A17: 전선영 | C17: 주 | D17: E | E17: E | F17: E | G17: N | H17: N | I17: OFF | J17: 주 | K17: D | L17: E | M17: E | N17: OFF | O17: VAC | P17: N | Q17: 주 | R17: E | S17: OFF | T17: E | U17: N | V17: N | W17: N | X17: 주 | Y17: 특휴 | Z17: E | AA17: E | AB17: E | AC17: VAC | AD17: OFF | AE17: =SUM(AT17:BD17) -> 11 | AF17: =COUNTIF(C17:AD17,"N") -> 6 | AK17: =COUNTIF($C17:$I17,AK$6) -> 1 | AL17: =COUNTIF($C17:$I17,AL$6&"*") -> 1 | AM17: =COUNTIF($J17:$P17,AM$6) -> 1 | AN17: =COUNTIF($J17:$P17,AN$6) -> 1 | AO17: =COUNTIF($Q17:$W17,AO$6) -> 1 | AP17: =COUNTIF($Q17:$W17,AP$6) -> 1 | AQ17: =COUNTIF($X17:$AD17,AQ$6) -> 1 | AR17: =COUNTIF($X17:$AD17,AR$6) -> 1 | AS17: 전선영 | AT17: =COUNTIF(C17:AD17,"특*") -> 1 | AU17: =COUNTIF(C17:AD17,"경가") -> 0 | AV17: =COUNTIF(C17:AD17,"병*") -> 0 | AW17: =COUNTIF(C17:AD17,"공*") -> 0 | AX17: =COUNTIF(C17:AD17,"생*")+COUNTIF(C17:AD17,"산전")+COUNTIF(C17:AD17,"검진") -> 0 | AY17: =COUNTIF(C17:AD17,"법*") -> 0 | AZ17: =COUNTIF(C17:AD17,"*OFF*") -> 4 | BA17: =COUNTIF(C17:AD17,"VAC*")+COUNTIF(C17:AD17,"휴가") -> 2 | BB17: =COUNTIF(B17:AC17,"출산*") -> 0 | BC17: =COUNTIF(C17:AD17,"*수면*") -> 0 | BD17: =COUNTIF(C17:AD17,"주") -> 4 | BE17: =SUM(AX17:BD17) -> 10 | BF17: =COUNTIF(J17:AD17,"N") -> 4 | BG17: =SUM(AU17:BD17) -> 10
A18: 이은지 | C18: OFF | D18: D | E18: D | F18: E | G18: E | H18: E | I18: 주 | J18: E | K18: E | L18: OFF | M18: E | N18: VAC | O18: D | P18: 주 | Q18: OFF | R18: 생휴 | S18: E | T18: N | U18: N | V18: N | W18: 주 | X18: off | Y18: D | Z18: D | AA18: E | AB18: VAC | AC18: D | AD18: 주 | AE18: =SUM(AT18:BD18) -> 11 | AF18: =COUNTIF(C18:AD18,"N") -> 3 | AK18: =COUNTIF($C18:$I18,AK$6) -> 1 | AL18: =COUNTIF($C18:$I18,AL$6&"*") -> 1 | AM18: =COUNTIF($J18:$P18,AM$6) -> 1 | AN18: =COUNTIF($J18:$P18,AN$6) -> 1 | AO18: =COUNTIF($Q18:$W18,AO$6) -> 1 | AP18: =COUNTIF($Q18:$W18,AP$6) -> 1 | AQ18: =COUNTIF($X18:$AD18,AQ$6) -> 1 | AR18: =COUNTIF($X18:$AD18,AR$6) -> 1 | AS18: 이은지 | AT18: =COUNTIF(C18:AD18,"특*") -> 0 | AU18: =COUNTIF(C18:AD18,"경가") -> 0 | AV18: =COUNTIF(C18:AD18,"병*") -> 0 | AW18: =COUNTIF(C18:AD18,"공*") -> 0 | AX18: =COUNTIF(C18:AD18,"생*")+COUNTIF(C18:AD18,"산전")+COUNTIF(C18:AD18,"검진") -> 1 | AY18: =COUNTIF(C18:AD18,"법*") -> 0 | AZ18: =COUNTIF(C18:AD18,"*OFF*") -> 4 | BA18: =COUNTIF(C18:AD18,"VAC*")+COUNTIF(C18:AD18,"휴가") -> 2 | BB18: =COUNTIF(B18:AC18,"출산*") -> 0 | BC18: =COUNTIF(C18:AD18,"*수면*") -> 0 | BD18: =COUNTIF(C18:AD18,"주") -> 4 | BE18: =SUM(AX18:BD18) -> 11 | BF18: =COUNTIF(J18:AD18,"N") -> 3 | BG18: =SUM(AU18:BD18) -> 11
... A44: 손수연 | C44: 주 | D44: OFF | E44: 생휴 | F44: E | G44: E | H44: E | I44: E | J44: 주 | K44: E | L44: N | M44: OFF | N44: E | O44: E | P44: E | Q44: 주 | R44: OFF | S44: E | T44: E | U44: E | V44: N | W44: N | X44: 주 | Y44: OFF | Z44: VAC | AA44: VAC | AB44: N | AC44: N | AD44: N | AE44: =SUM(AT44:BD44) -> 11 | AF44: =COUNTIF(C44:AD44,"N") -> 6 | AK44: =COUNTIF($C44:$I44,AK$6) -> 1 | AL44: =COUNTIF($C44:$I44,AL$6&"*") -> 1 | AM44: =COUNTIF($J44:$P44,AM$6) -> 1 | AN44: =COUNTIF($J44:$P44,AN$6) -> 1 | AO44: =COUNTIF($Q44:$W44,AO$6) -> 1 | AP44: =COUNTIF($Q44:$W44,AP$6) -> 1 | AQ44: =COUNTIF($X44:$AD44,AQ$6) -> 1 | AR44: =COUNTIF($X44:$AD44,AR$6) -> 1 | AS44: 손수연 | AT44: =COUNTIF(C44:AD44,"특*") -> 0 | AU44: =COUNTIF(C44:AD44,"경가") -> 0 | AV44: =COUNTIF(C44:AD44,"병*") -> 0 | AW44: =COUNTIF(C44:AD44,"공*") -> 0 | AX44: =COUNTIF(C44:AD44,"생*")+COUNTIF(C44:AD44,"산전")+COUNTIF(C44:AD44,"검진") -> 1 | AY44: =COUNTIF(C44:AD44,"법*") -> 0 | AZ44: =COUNTIF(C44:AD44,"*OFF*") -> 4 | BA44: =COUNTIF(C44:AD44,"VAC*")+COUNTIF(C44:AD44,"휴가") -> 2 | BB44: =COUNTIF(B44:AC44,"출산*") -> 0 | BC44: =COUNTIF(C44:AD44,"*수면*") -> 0 | BD44: =COUNTIF(C44:AD44,"주") -> 4 | BE44: =SUM(AX44:BD44) -> 11 | BF44: =COUNTIF(J44:AD44,"N") -> 6 | BG44: =SUM(AU44:BD44) -> 11
A45: 김현진 | AE45: =SUM(AT45:BD45) -> 0 | AF45: =COUNTIF(C45:AD45,"N") -> 0 | AK45: =COUNTIF($C45:$I45,AK$6) -> 0 | AL45: =COUNTIF($C45:$I45,AL$6&"*") -> 0 | AM45: =COUNTIF($J45:$P45,AM$6) -> 0 | AN45: =COUNTIF($J45:$P45,AN$6) -> 0 | AO45: =COUNTIF($Q45:$W45,AO$6) -> 0 | AP45: =COUNTIF($Q45:$W45,AP$6) -> 0 | AQ45: =COUNTIF($X45:$AD45,AQ$6) -> 0 | AR45: =COUNTIF($X45:$AD45,AR$6) -> 0 | AS45: 김현진 | AT45: =COUNTIF(C45:AD45,"특*") -> 0 | AU45: =COUNTIF(C45:AD45,"경가") -> 0 | AV45: =COUNTIF(C45:AD45,"병*") -> 0 | AW45: =COUNTIF(C45:AD45,"공*") -> 0 | AX45: =COUNTIF(C45:AD45,"생*")+COUNTIF(C45:AD45,"산전")+COUNTIF(C45:AD45,"검진") -> 0 | AY45: =COUNTIF(C45:AD45,"법*") -> 0 | AZ45: =COUNTIF(C45:AD45,"*OFF*") -> 0 | BA45: =COUNTIF(C45:AD45,"VAC*")+COUNTIF(C45:AD45,"휴가") -> 0 | BB45: =COUNTIF(B45:AC45,"출산*") -> 0 | BC45: =COUNTIF(C45:AD45,"*수면*") -> 0 | BD45: =COUNTIF(C45:AD45,"주") -> 0 | BE45: =SUM(AX45:BD45) -> 0 | BF45: =COUNTIF(J45:AD45,"N") -> 0 | BG45: =SUM(AU45:BD45) -> 0
A46: 박병호 | AE46: =SUM(AT46:BD46) -> 0 | AF46: =COUNTIF(C46:AD46,"N") -> 0 | AK46: =COUNTIF($C46:$I46,AK$6) -> 0 | AL46: =COUNTIF($C46:$I46,AL$6&"*") -> 0 | AM46: =COUNTIF($J46:$P46,AM$6) -> 0 | AN46: =COUNTIF($J46:$P46,AN$6) -> 0 | AO46: =COUNTIF($Q46:$W46,AO$6) -> 0 | AP46: =COUNTIF($Q46:$W46,AP$6) -> 0 | AQ46: =COUNTIF($X46:$AD46,AQ$6) -> 0 | AR46: =COUNTIF($X46:$AD46,AR$6) -> 0 | AS46: 박병호 | AT46: =COUNTIF(C46:AD46,"특*") -> 0 | AU46: =COUNTIF(C46:AD46,"경가") -> 0 | AV46: =COUNTIF(C46:AD46,"병*") -> 0 | AW46: =COUNTIF(C46:AD46,"공*") -> 0 | AX46: =COUNTIF(C46:AD46,"생*")+COUNTIF(C46:AD46,"산전")+COUNTIF(C46:AD46,"검진") -> 0 | AY46: =COUNTIF(C46:AD46,"법*") -> 0 | AZ46: =COUNTIF(C46:AD46,"*OFF*") -> 0 | BA46: =COUNTIF(C46:AD46,"VAC*")+COUNTIF(C46:AD46,"휴가") -> 0 | BB46: =COUNTIF(B46:AC46,"출산*") -> 0 | BC46: =COUNTIF(C46:AD46,"*수면*") -> 0 | BD46: =COUNTIF(C46:AD46,"주") -> 0 | BE46: =SUM(AX46:BD46) -> 0 | BF46: =COUNTIF(J46:AD46,"N") -> 0 | BG46: =SUM(AU46:BD46) -> 0
A47: 배수영 | AE47: =SUM(AT47:BD47) -> 0 | AF47: =COUNTIF(C47:AD47,"N") -> 0 | AK47: =COUNTIF($C47:$I47,AK$6) -> 0 | AL47: =COUNTIF($C47:$I47,AL$6&"*") -> 0 | AM47: =COUNTIF($J47:$P47,AM$6) -> 0 | AN47: =COUNTIF($J47:$P47,AN$6) -> 0 | AO47: =COUNTIF($Q47:$W47,AO$6) -> 0 | AP47: =COUNTIF($Q47:$W47,AP$6) -> 0 | AQ47: =COUNTIF($X47:$AD47,AQ$6) -> 0 | AR47: =COUNTIF($X47:$AD47,AR$6) -> 0 | AS47: 배수영 | AT47: =COUNTIF(C47:AD47,"특*") -> 0 | AU47: =COUNTIF(C47:AD47,"경가") -> 0 | AV47: =COUNTIF(C47:AD47,"병*") -> 0 | AW47: =COUNTIF(C47:AD47,"공*") -> 0 | AX47: =COUNTIF(C47:AD47,"생*")+COUNTIF(C47:AD47,"산전")+COUNTIF(C47:AD47,"검진") -> 0 | AY47: =COUNTIF(C47:AD47,"법*") -> 0 | AZ47: =COUNTIF(C47:AD47,"*OFF*") -> 0 | BA47: =COUNTIF(C47:AD47,"VAC*")+COUNTIF(C47:AD47,"휴가") -> 0 | BB47: =COUNTIF(B47:AC47,"출산*") -> 0 | BC47: =COUNTIF(C47:AD47,"*수면*") -> 0 | BD47: =COUNTIF(C47:AD47,"주") -> 0 | BE47: =SUM(AX47:BD47) -> 0 | BF47: =COUNTIF(J47:AD47,"N") -> 0 | BG47: =SUM(AU47:BD47) -> 0
A48: 김현빈 | AE48: =SUM(AT48:BD48) -> 0 | AF48: =COUNTIF(C48:AD48,"N") -> 0 | AK48: =COUNTIF($C48:$I48,AK$6) -> 0 | AL48: =COUNTIF($C48:$I48,AL$6&"*") -> 0 | AM48: =COUNTIF($J48:$P48,AM$6) -> 0 | AN48: =COUNTIF($J48:$P48,AN$6) -> 0 | AO48: =COUNTIF($Q48:$W48,AO$6) -> 0 | AP48: =COUNTIF($Q48:$W48,AP$6) -> 0 | AQ48: =COUNTIF($X48:$AD48,AQ$6) -> 0 | AR48: =COUNTIF($X48:$AD48,AR$6) -> 0 | AS48: 김현빈 | AT48: =COUNTIF(C48:AD48,"특*") -> 0 | AU48: =COUNTIF(C48:AD48,"경가") -> 0 | AV48: =COUNTIF(C48:AD48,"병*") -> 0 | AW48: =COUNTIF(C48:AD48,"공*") -> 0 | AX48: =COUNTIF(C48:AD48,"생*")+COUNTIF(C48:AD48,"산전")+COUNTIF(C48:AD48,"검진") -> 0 | AY48: =COUNTIF(C48:AD48,"법*") -> 0 | AZ48: =COUNTIF(C48:AD48,"*OFF*") -> 0 | BA48: =COUNTIF(C48:AD48,"VAC*")+COUNTIF(C48:AD48,"휴가") -> 0 | BB48: =COUNTIF(B48:AC48,"출산*") -> 0 | BC48: =COUNTIF(C48:AD48,"*수면*") -> 0 | BD48: =COUNTIF(C48:AD48,"주") -> 0 | BE48: =SUM(AX48:BD48) -> 0 | BF48: =COUNTIF(J48:AD48,"N") -> 0 | BG48: =SUM(AU48:BD48) -> 0
A50: D | C50: =COUNTIF(C$7:C$45,$A50) -> 7 | D50: =COUNTIF(D$7:D$45,$A50) -> 7 | E50: =COUNTIF(E$7:E$45,$A50) -> 8 | F50: =COUNTIF(F$7:F$45,$A50) -> 7 | G50: =COUNTIF(G$7:G$45,$A50) -> 8 | H50: =COUNTIF(H$7:H$45,$A50) -> 8 | I50: =COUNTIF(I$7:I$45,$A50) -> 7 | J50: =COUNTIF(J$7:J$45,$A50) -> 7 | ... AD50: =COUNTIF(AD$7:AD$45,$A50) -> 7
A51: E | C51: =COUNTIF(C$7:C$45,$A51) -> 8 | D51: =COUNTIF(D$7:D$45,$A51) -> 8 | E51: =COUNTIF(E$7:E$45,$A51) -> 8 | F51: =COUNTIF(F$7:F$45,$A51) -> 8 | G51: =COUNTIF(G$7:G$45,$A51) -> 8 | H51: =COUNTIF(H$7:H$45,$A51) -> 8 | I51: =COUNTIF(I$7:I$45,$A51) -> 8 | J51: =COUNTIF(J$7:J$45,$A51) -> 8 | ... AD51: =COUNTIF(AD$7:AD$45,$A51) -> 8
A52: N | C52: =COUNTIF(C$7:C$45,$A52) -> 7 | D52: =COUNTIF(D$7:D$45,$A52) -> 7 | E52: =COUNTIF(E$7:E$45,$A52) -> 7 | F52: =COUNTIF(F$7:F$45,$A52) -> 7 | G52: =COUNTIF(G$7:G$45,$A52) -> 7 | H52: =COUNTIF(H$7:H$45,$A52) -> 7 | I52: =COUNTIF(I$7:I$45,$A52) -> 7 | J52: =COUNTIF(J$7:J$45,$A52) -> 7 | ... AD52: =COUNTIF(AD$7:AD$45,$A52) -> 7
A53: 중 | C53: =COUNTIF(C$7:C$45,$A53) -> 0 | D53: =COUNTIF(D$7:D$45,$A53) -> 0 | E53: =COUNTIF(E$7:E$45,$A53) -> 0 | F53: =COUNTIF(F$7:F$45,$A53) -> 0 | G53: =COUNTIF(G$7:G$45,$A53) -> 0 | H53: =COUNTIF(H$7:H$45,$A53) -> 0 | I53: =COUNTIF(I$7:I$45,$A53) -> 0 | J53: =COUNTIF(J$7:J$45,$A53) -> 0 | ... AD53: =COUNTIF(AD$7:AD$45,$A53) -> 0
A54: 중2 | C54: =COUNTIF(C$7:C$45,$A54) -> 0 | D54: =COUNTIF(D$7:D$45,$A54) -> 2 | E54: =COUNTIF(E$7:E$45,$A54) -> 0 | F54: =COUNTIF(F$7:F$45,$A54) -> 0 | G54: =COUNTIF(G$7:G$45,$A54) -> 0 | H54: =COUNTIF(H$7:H$45,$A54) -> 0 | I54: =COUNTIF(I$7:I$45,$A54) -> 0 | J54: =COUNTIF(J$7:J$45,$A54) -> 0 | ... AD54: =COUNTIF(AD$7:AD$45,$A54) -> 0

Sheet 원번표(수정불가)
J3: ='변경(260104_260131)'!J3:U3 -> 2026.01.04._26.01.31. | AB3: 간호사 38(파트장포함)
C5: ='변경(260104_260131)'!C5 -> 4 | D5: ='변경(260104_260131)'!D5 -> 5 | E5: ='변경(260104_260131)'!E5 -> 6 | F5: ='변경(260104_260131)'!F5 -> 7 | G5: ='변경(260104_260131)'!G5 -> 8 | H5: ='변경(260104_260131)'!H5 -> 9 | I5: ='변경(260104_260131)'!I5 -> 10 | J5: ='변경(260104_260131)'!J5 -> 11 | ... AD5: ='변경(260104_260131)'!AD5 -> 31 | AE5: 총 | AF5: 총 | AK5: 1 | AM5: 2 | AO5: 3 | AQ5: 4
B6: 비고 | C6: ='변경(260104_260131)'!C6 -> 일 | D6: ='변경(260104_260131)'!D6 -> 월 | E6: ='변경(260104_260131)'!E6 -> 화 | F6: ='변경(260104_260131)'!F6 -> 수 | G6: ='변경(260104_260131)'!G6 -> 목 | H6: ='변경(260104_260131)'!H6 -> 금 | I6: ='변경(260104_260131)'!I6 -> 토 | J6: ='변경(260104_260131)'!J6 -> 일 | ... AD6: ='변경(260104_260131)'!AD6 -> 토 | AE6: OFF | AF6: N | AK6: 주 | AL6: OFF | AM6: 주 | AN6: OFF | AO6: 주 | AP6: OFF | AQ6: 주 | AR6: OFF | AT6: 특휴 | AU6: 경가 | AV6: 병가 | AW6: 공 | AX6: 생휴 | AY6: 법휴 | AZ6: OFF | BA6: VAC | BB6: 출산 | BC6: 수면 | BD6: 주휴 | BE6: OFF계 | BF6: N | BG6: 병가,OFF,공휴 포함
A7: 이경희 | C7: D | D7: 주 | E7: D | F7: off | G7: D | H7: D | I7: D | J7: D | K7: 주 | L7: D | M7: E | N7: N | O7: OFF | P7: N | Q7: OFF | R7: 주 | S7: E | T7: E | U7: N | V7: VAC | W7: E | X7: E | Y7: 주 | Z7: D | AA7: N | AB7: OFF | AC7: 생휴 | AD7: VAC | AE7: =SUM(AT7:BD7) -> 11 | AF7: =COUNTIF(C7:AD7,"N") -> 4 | AK7: =COUNTIF($C7:$I7,AK$6) -> 1 | AL7: =COUNTIF($C7:$I7,AL$6&"*") -> 1 | AM7: =COUNTIF($J7:$P7,AM$6) -> 1 | AN7: =COUNTIF($J7:$P7,AN$6) -> 1 | AO7: =COUNTIF($Q7:$W7,AO$6) -> 1 | AP7: =COUNTIF($Q7:$W7,AP$6) -> 1 | AQ7: =COUNTIF($X7:$AD7,AQ$6) -> 1 | AR7: =COUNTIF($X7:$AD7,AR$6) -> 1 | AS7: 이경희 | AT7: =COUNTIF(C7:AD7,"특*") -> 0 | AU7: =COUNTIF(C7:AD7,"경가") -> 0 | AV7: =COUNTIF(C7:AD7,"병*") -> 0 | AW7: =COUNTIF(C7:AD7,"공*") -> 0 | AX7: =COUNTIF(C7:AD7,"생*")+COUNTIF(C7:AD7,"산전")+COUNTIF(C7:AD7,"검진") -> 1 | AY7: =COUNTIF(C7:AD7,"법*") -> 0 | AZ7: =COUNTIF(C7:AD7,"*OFF*") -> 4 | BA7: =COUNTIF(C7:AD7,"VAC*")+COUNTIF(C7:AD7,"휴가") -> 2 | BB7: =COUNTIF(C7:AD7,"출산") -> 0 | BC7: =COUNTIF(C7:AD7,"*수면*") -> 0 | BD7: =COUNTIF(C7:AD7,"주") -> 4 | BE7: =SUM(AX7:BD7) -> 11 | BF7: =COUNTIF(J7:AD7,"N") -> 4 | BG7: =SUM(AU7:BD7) -> 11
A8: 오선영 | C8: N | D8: 휴가 | E8: 주 | F8: D | G8: OFF | H8: N | I8: N | J8: OFF | K8: 생휴 | L8: 주 | M8: D | N8: D | O8: 번표 | P8: D | Q8: D | R8: OFF | S8: 주 | T8: 휴가 | U8: D | V8: D | W8: D | X8: D | Y8: E | Z8: 주 | AA8: D | AB8: D | AC8: OFF | AD8: N | AE8: =SUM(AT8:BD8) -> 11 | AF8: =COUNTIF(C8:AD8,"N") -> 4 | AK8: =COUNTIF($C8:$I8,AK$6) -> 1 | AL8: =COUNTIF($C8:$I8,AL$6&"*") -> 1 | AM8: =COUNTIF($J8:$P8,AM$6) -> 1 | AN8: =COUNTIF($J8:$P8,AN$6) -> 1 | AO8: =COUNTIF($Q8:$W8,AO$6) -> 1 | AP8: =COUNTIF($Q8:$W8,AP$6) -> 1 | AQ8: =COUNTIF($X8:$AD8,AQ$6) -> 1 | AR8: =COUNTIF($X8:$AD8,AR$6) -> 1 | AS8: 오선영 | AT8: =COUNTIF(C8:AD8,"특*") -> 0 | AU8: =COUNTIF(C8:AD8,"경가") -> 0 | AV8: =COUNTIF(C8:AD8,"병*") -> 0 | AW8: =COUNTIF(C8:AD8,"공*") -> 0 | AX8: =COUNTIF(C8:AD8,"생*")+COUNTIF(C8:AD8,"산전")+COUNTIF(C8:AD8,"검진") -> 1 | AY8: =COUNTIF(C8:AD8,"법*") -> 0 | AZ8: =COUNTIF(C8:AD8,"*OFF*") -> 4 | BA8: =COUNTIF(C8:AD8,"VAC*")+COUNTIF(C8:AD8,"휴가") -> 2 | BB8: =COUNTIF(C8:AD8,"출산") -> 0 | BC8: =COUNTIF(C8:AD8,"*수면*") -> 0 | BD8: =COUNTIF(C8:AD8,"주") -> 4 | BE8: =SUM(AX8:BD8) -> 11 | BF8: =COUNTIF(J8:AD8,"N") -> 1 | BG8: =SUM(AU8:BD8) -> 11
A9: 우영미 | C9: E | D9: E | E9: E | F9: E | G9: 주 | H9: OFF | I9: VAC | J9: E | K9: E | L9: N | M9: N | N9: 주 | O9: off | P9: E | Q9: E | R9: OFF | S9: N | T9: N | U9: 주 | V9: VAC | W9: 생휴 | X9: off | Y9: D | Z9: E | AA9: E | AB9: 주 | AC9: D | AD9: E | AE9: =SUM(AT9:BD9) -> 11 | AF9: =COUNTIF(C9:AD9,"N") -> 4 | AK9: =COUNTIF($C9:$I9,AK$6) -> 1 | AL9: =COUNTIF($C9:$I9,AL$6&"*") -> 1 | AM9: =COUNTIF($J9:$P9,AM$6) -> 1 | AN9: =COUNTIF($J9:$P9,AN$6) -> 1 | AO9: =COUNTIF($Q9:$W9,AO$6) -> 1 | AP9: =COUNTIF($Q9:$W9,AP$6) -> 1 | AQ9: =COUNTIF($X9:$AD9,AQ$6) -> 1 | AR9: =COUNTIF($X9:$AD9,AR$6) -> 1 | AS9: 우영미 | AT9: =COUNTIF(C9:AD9,"특*") -> 0 | AU9: =COUNTIF(C9:AD9,"경가") -> 0 | AV9: =COUNTIF(C9:AD9,"병*") -> 0 | AW9: =COUNTIF(C9:AD9,"공*") -> 0 | AX9: =COUNTIF(C9:AD9,"생*")+COUNTIF(C9:AD9,"산전")+COUNTIF(C9:AD9,"검진") -> 1 | AY9: =COUNTIF(C9:AD9,"법*") -> 0 | AZ9: =COUNTIF(C9:AD9,"*OFF*") -> 4 | BA9: =COUNTIF(C9:AD9,"VAC*")+COUNTIF(C9:AD9,"휴가") -> 2 | BB9: =COUNTIF(C9:AD9,"출산") -> 0 | BC9: =COUNTIF(C9:AD9,"*수면*") -> 0 | BD9: =COUNTIF(C9:AD9,"주") -> 4 | BE9: =SUM(AX9:BD9) -> 11 | BF9: =COUNTIF(J9:AD9,"N") -> 4 | BG9: =SUM(AU9:BD9) -> 11
A10: 전상배 | C10: VAC | D10: 주 | E10: D | F10: D | G10: D | H10: D | I10: OFF | J10: OFF | K10: 주 | L10: D | M10: D | N10: N | O10: N | P10: N | Q10: OFF | R10: 주 | S10: VAC | T10: D | U10: D | V10: N | W10: N | X10: N | Y10: 주 | Z10: OFF | AA10: D | AB10: D | AC10: D | AD10: VAC | AE10: =SUM(AT10:BD10) -> 11 | AF10: =COUNTIF(C10:AD10,"N") -> 6 | AK10: =COUNTIF($C10:$I10,AK$6) -> 1 | AL10: =COUNTIF($C10:$I10,AL$6&"*") -> 1 | AM10: =COUNTIF($J10:$P10,AM$6) -> 1 | AN10: =COUNTIF($J10:$P10,AN$6) -> 1 | AO10: =COUNTIF($Q10:$W10,AO$6) -> 1 | AP10: =COUNTIF($Q10:$W10,AP$6) -> 1 | AQ10: =COUNTIF($X10:$AD10,AQ$6) -> 1 | AR10: =COUNTIF($X10:$AD10,AR$6) -> 1 | AS10: 전상배 | AT10: =COUNTIF(C10:AD10,"특*") -> 0 | AU10: =COUNTIF(C10:AD10,"경가") -> 0 | AV10: =COUNTIF(C10:AD10,"병*") -> 0 | AW10: =COUNTIF(C10:AD10,"공*") -> 0 | AX10: =COUNTIF(C10:AD10,"생*")+COUNTIF(C10:AD10,"산전")+COUNTIF(C10:AD10,"검진") -> 0 | AY10: =COUNTIF(C10:AD10,"법*") -> 0 | AZ10: =COUNTIF(C10:AD10,"*OFF*") -> 4 | BA10: =COUNTIF(C10:AD10,"VAC*")+COUNTIF(C10:AD10,"휴가") -> 3 | BB10: =COUNTIF(C10:AD10,"출산") -> 0 | BC10: =COUNTIF(C10:AD10,"*수면*") -> 0 | BD10: =COUNTIF(C10:AD10,"주") -> 4 | BE10: =SUM(AX10:BD10) -> 11 | BF10: =COUNTIF(J10:AD10,"N") -> 6 | BG10: =SUM(AU10:BD10) -> 11
A11: 안일심 | C11: 주 | D11: OFF | E11: 특휴 | F11: D | G11: D | H11: OFF | I11: 생휴 | J11: 주 | K11: OFF | L11: E | M11: OFF | N11: D | O11: D | P11: N | Q11: 주 | R11: E | S11: N | T11: OFF | U11: OFF | V11: N | W11: N | X11: 주 | Y11: OFF | Z11: E | AA11: E | AB11: OFF | AC11: N | AD11: N | AE11: =SUM(AT11:BD11) -> 14 | AF11: =COUNTIF(C11:AD11,"N") -> 6 | AK11: =COUNTIF($C11:$I11,AK$6) -> 1 | AL11: =COUNTIF($C11:$I11,AL$6&"*") -> 2 | AM11: =COUNTIF($J11:$P11,AM$6) -> 1 | AN11: =COUNTIF($J11:$P11,AN$6) -> 2 | AO11: =COUNTIF($Q11:$W11,AO$6) -> 1 | AP11: =COUNTIF($Q11:$W11,AP$6) -> 2 | AQ11: =COUNTIF($X11:$AD11,AQ$6) -> 1 | AR11: =COUNTIF($X11:$AD11,AR$6) -> 2 | AS11: 안일심 | AT11: =COUNTIF(C11:AD11,"특*") -> 1 | AU11: =COUNTIF(C11:AD11,"경가") -> 0 | AV11: =COUNTIF(C11:AD11,"병*") -> 0 | AW11: =COUNTIF(C11:AD11,"공*") -> 0 | AX11: =COUNTIF(C11:AD11,"생*")+COUNTIF(C11:AD11,"산전")+COUNTIF(C11:AD11,"검진") -> 1 | AY11: =COUNTIF(C11:AD11,"법*") -> 0 | AZ11: =COUNTIF(C11:AD11,"*OFF*") -> 8 | BA11: =COUNTIF(C11:AD11,"VAC*")+COUNTIF(C11:AD11,"휴가") -> 0 | BB11: =COUNTIF(C11:AD11,"출산") -> 0 | BC11: =COUNTIF(C11:AD11,"*수면*") -> 0 | BD11: =COUNTIF(C11:AD11,"주") -> 4 | BE11: =SUM(AX11:BD11) -> 13 | BF11: =COUNTIF(J11:AD11,"N") -> 6 | BG11: =SUM(AU11:BD11) -> 13
A12: 조은애 | C12: 수면12 | D12: N | E12: N | F12: OFF | G12: OFF | H12: 주 | I12: D | J12: OFF | K12: D | L12: D | M12: OFF | N12: D | O12: 주 | P12: 생휴 | Q12: N | R12: N | S12: OFF | T12: OFF | U12: E | V12: 주 | W12: E | X12: E | Y12: OFF | Z12: N | AA12: N | AB12: off | AC12: 주 | AD12: D | AE12: =SUM(AT12:BD12) -> 14 | AF12: =COUNTIF(C12:AD12,"N") -> 6 | AK12: =COUNTIF($C12:$I12,AK$6) -> 1 | AL12: =COUNTIF($C12:$I12,AL$6&"*") -> 2 | AM12: =COUNTIF($J12:$P12,AM$6) -> 1 | AN12: =COUNTIF($J12:$P12,AN$6) -> 2 | AO12: =COUNTIF($Q12:$W12,AO$6) -> 1 | AP12: =COUNTIF($Q12:$W12,AP$6) -> 2 | AQ12: =COUNTIF($X12:$AD12,AQ$6) -> 1 | AR12: =COUNTIF($X12:$AD12,AR$6) -> 2 | AS12: 조은애 | AT12: =COUNTIF(C12:AD12,"특*") -> 0 | AU12: =COUNTIF(C12:AD12,"경가") -> 0 | AV12: =COUNTIF(C12:AD12,"병*") -> 0 | AW12: =COUNTIF(C12:AD12,"공*") -> 0 | AX12: =COUNTIF(C12:AD12,"생*")+COUNTIF(C12:AD12,"산전")+COUNTIF(C12:AD12,"검진") -> 1 | AY12: =COUNTIF(C12:AD12,"법*") -> 0 | AZ12: =COUNTIF(C12:AD12,"*OFF*") -> 8 | BA12: =COUNTIF(C12:AD12,"VAC*")+COUNTIF(C12:AD12,"휴가") -> 0 | BB12: =COUNTIF(C12:AD12,"출산") -> 0 | BC12: =COUNTIF(C12:AD12,"*수면*") -> 1 | BD12: =COUNTIF(C12:AD12,"주") -> 4 | BE12: =SUM(AX12:BD12) -> 14 | BF12: =COUNTIF(J12:AD12,"N") -> 4 | BG12: =SUM(AU12:BD12) -> 14
A13: 우혜린 | C13: E | D13: OFF | E13: E | F13: N | G13: N | H13: N | I13: 주 | J13: OFF | K13: E | L13: E | M13: E | N13: E | O13: VAC | P13: 주 | Q13: OFF | R13: 생휴 | S13: D | T13: D | U13: N | V13: N | W13: 주 | X13: off | Y13: E | Z13: E | AA13: E | AB13: N | AC13: VAC | AD13: 주 | AE13: =SUM(AT13:BD13) -> 11 | AF13: =COUNTIF(C13:AD13,"N") -> 6 | AK13: =COUNTIF($C13:$I13,AK$6) -> 1 | AL13: =COUNTIF($C13:$I13,AL$6&"*") -> 1 | AM13: =COUNTIF($J13:$P13,AM$6) -> 1 | AN13: =COUNTIF($J13:$P13,AN$6) -> 1 | AO13: =COUNTIF($Q13:$W13,AO$6) -> 1 | AP13: =COUNTIF($Q13:$W13,AP$6) -> 1 | AQ13: =COUNTIF($X13:$AD13,AQ$6) -> 1 | AR13: =COUNTIF($X13:$AD13,AR$6) -> 1 | AS13: 우혜린 | AT13: =COUNTIF(C13:AD13,"특*") -> 0 | AU13: =COUNTIF(C13:AD13,"경가") -> 0 | AV13: =COUNTIF(C13:AD13,"병*") -> 0 | AW13: =COUNTIF(C13:AD13,"공*") -> 0 | AX13: =COUNTIF(C13:AD13,"생*")+COUNTIF(C13:AD13,"산전")+COUNTIF(C13:AD13,"검진") -> 1 | AY13: =COUNTIF(C13:AD13,"법*") -> 0 | AZ13: =COUNTIF(C13:AD13,"*OFF*") -> 4 | BA13: =COUNTIF(C13:AD13,"VAC*")+COUNTIF(C13:AD13,"휴가") -> 2 | BB13: =COUNTIF(C13:AD13,"출산") -> 0 | BC13: =COUNTIF(C13:AD13,"*수면*") -> 0 | BD13: =COUNTIF(C13:AD13,"주") -> 4 | BE13: =SUM(AX13:BD13) -> 11 | BF13: =COUNTIF(J13:AD13,"N") -> 3 | BG13: =SUM(AU13:BD13) -> 11
A14: 유지연 | C14: D | D14: D | E14: D | F14: 주 | G14: off | H14: E | I14: E | J14: N | K14: N | L14: OFF | M14: 주 | N14: E | O14: E | P14: E | Q14: off | R14: 생휴 | S14: 수면12 | T14: 주 | U14: D | V14: VAC | W14: E | X14: N | Y14: N | Z14: N | AA14: 주 | AB14: OFF | AC14: E | AD14: E | AE14: =SUM(AT14:BD14) -> 11 | AF14: =COUNTIF(C14:AD14,"N") -> 5 | AK14: =COUNTIF($C14:$I14,AK$6) -> 1 | AL14: =COUNTIF($C14:$I14,AL$6&"*") -> 1 | AM14: =COUNTIF($J14:$P14,AM$6) -> 1 | AN14: =COUNTIF($J14:$P14,AN$6) -> 1 | AO14: =COUNTIF($Q14:$W14,AO$6) -> 1 | AP14: =COUNTIF($Q14:$W14,AP$6) -> 1 | AQ14: =COUNTIF($X14:$AD14,AQ$6) -> 1 | AR14: =COUNTIF($X14:$AD14,AR$6) -> 1 | AS14: 유지연 | AT14: =COUNTIF(C14:AD14,"특*") -> 0 | AU14: =COUNTIF(C14:AD14,"경가") -> 0 | AV14: =COUNTIF(C14:AD14,"병*") -> 0 | AW14: =COUNTIF(C14:AD14,"공*") -> 0 | AX14: =COUNTIF(C14:AD14,"생*")+COUNTIF(C14:AD14,"산전")+COUNTIF(C14:AD14,"검진") -> 1 | AY14: =COUNTIF(C14:AD14,"법*") -> 0 | AZ14: =COUNTIF(C14:AD14,"*OFF*") -> 4 | BA14: =COUNTIF(C14:AD14,"VAC*")+COUNTIF(C14:AD14,"휴가") -> 1 | BB14: =COUNTIF(C14:AD14,"출산") -> 0 | BC14: =COUNTIF(C14:AD14,"*수면*") -> 1 | BD14: =COUNTIF(C14:AD14,"주") -> 4 | BE14: =SUM(AX14:BD14) -> 11 | BF14: =COUNTIF(J14:AD14,"N") -> 5 | BG14: =SUM(AU14:BD14) -> 11
A15: 서희정 | C15: N | D15: OFF | E15: VAC | F15: E | G15: E | H15: 생휴 | I15: 주 | J15: VAC | K15: OFF | L15: E | M15: N | N15: N | O15: N | P15: 주 | Q15: OFF | R15: D | S15: E | T15: E | U15: E | V15: E | W15: 주 | X15: E | Y15: N | Z15: OFF | AA15: E | AB15: E | AC15: N | AD15: 주 | AE15: =SUM(AT15:BD15) -> 11 | AF15: =COUNTIF(C15:AD15,"N") -> 6 | AK15: =COUNTIF($C15:$I15,AK$6) -> 1 | AL15: =COUNTIF($C15:$I15,AL$6&"*") -> 1 | AM15: =COUNTIF($J15:$P15,AM$6) -> 1 | AN15: =COUNTIF($J15:$P15,AN$6) -> 1 | AO15: =COUNTIF($Q15:$W15,AO$6) -> 1 | AP15: =COUNTIF($Q15:$W15,AP$6) -> 1 | AQ15: =COUNTIF($X15:$AD15,AQ$6) -> 1 | AR15: =COUNTIF($X15:$AD15,AR$6) -> 1 | AS15: 서희정 | AT15: =COUNTIF(C15:AD15,"특*") -> 0 | AU15: =COUNTIF(C15:AD15,"경가") -> 0 | AV15: =COUNTIF(C15:AD15,"병*") -> 0 | AW15: =COUNTIF(C15:AD15,"공*") -> 0 | AX15: =COUNTIF(C15:AD15,"생*")+COUNTIF(C15:AD15,"산전")+COUNTIF(C15:AD15,"검진") -> 1 | AY15: =COUNTIF(C15:AD15,"법*") -> 0 | AZ15: =COUNTIF(C15:AD15,"*OFF*") -> 4 | BA15: =COUNTIF(C15:AD15,"VAC*")+COUNTIF(C15:AD15,"휴가") -> 2 | BB15: =COUNTIF(C15:AD15,"출산") -> 0 | BC15: =COUNTIF(C15:AD15,"*수면*") -> 0 | BD15: =COUNTIF(C15:AD15,"주") -> 4 | BE15: =SUM(AX15:BD15) -> 11 | BF15: =COUNTIF(J15:AD15,"N") -> 5 | BG15: =SUM(AU15:BD15) -> 11
A16: 김도연 | C16: 주 | D16: 중2 | E16: N | F16: N | G16: OFF | H16: OFF | I16: N | J16: 주 | K16: OFF | L16: OFF | M16: D | N16: D | O16: 중2 | P16: VAC | Q16: 주 | R16: E | S16: N | T16: OFF | U16: OFF | V16: 중2 | W16: D | X16: 주 | Y16: N | Z16: 생휴 | AA16: OFF | AB16: 중2 | AC16: OFF | AD16: D | AE16: =SUM(AT16:BD16) -> 14 | AF16: =COUNTIF(C16:AD16,"N") -> 5 | AK16: =COUNTIF($C16:$I16,AK$6) -> 1 | AL16: =COUNTIF($C16:$I16,AL$6&"*") -> 2 | AM16: =COUNTIF($J16:$P16,AM$6) -> 1 | AN16: =COUNTIF($J16:$P16,AN$6) -> 2 | AO16: =COUNTIF($Q16:$W16,AO$6) -> 1 | AP16: =COUNTIF($Q16:$W16,AP$6) -> 2 | AQ16: =COUNTIF($X16:$AD16,AQ$6) -> 1 | AR16: =COUNTIF($X16:$AD16,AR$6) -> 2 | AS16: 김도연 | AT16: =COUNTIF(C16:AD16,"특*") -> 0 | AU16: =COUNTIF(C16:AD16,"경가") -> 0 | AV16: =COUNTIF(C16:AD16,"병*") -> 0 | AW16: =COUNTIF(C16:AD16,"공*") -> 0 | AX16: =COUNTIF(C16:AD16,"생*")+COUNTIF(C16:AD16,"산전")+COUNTIF(C16:AD16,"검진") -> 1 | AY16: =COUNTIF(C16:AD16,"법*") -> 0 | AZ16: =COUNTIF(C16:AD16,"*OFF*") -> 8 | BA16: =COUNTIF(C16:AD16,"VAC*")+COUNTIF(C16:AD16,"휴가") -> 1 | BB16: =COUNTIF(C16:AD16,"출산") -> 0 | BC16: =COUNTIF(C16:AD16,"*수면*") -> 0 | BD16: =COUNTIF(C16:AD16,"주") -> 4 | BE16: =SUM(AX16:BD16) -> 14 | BF16: =COUNTIF(J16:AD16,"N") -> 2 | BG16: =SUM(AU16:BD16) -> 14
A17: 전선영 | C17: 주 | D17: E | E17: E | F17: E | G17: N | H17: N | I17: OFF | J17: 주 | K17: D | L17: E | M17: E | N17: OFF | O17: VAC | P17: N | Q17: 주 | R17: E | S17: OFF | T17: E | U17: N | V17: N | W17: N | X17: 주 | Y17: 특휴 | Z17: E | AA17: E | AB17: E | AC17: VAC | AD17: OFF | AE17: =SUM(AT17:BD17) -> 11 | AF17: =COUNTIF(C17:AD17,"N") -> 6 | AK17: =COUNTIF($C17:$I17,AK$6) -> 1 | AL17: =COUNTIF($C17:$I17,AL$6&"*") -> 1 | AM17: =COUNTIF($J17:$P17,AM$6) -> 1 | AN17: =COUNTIF($J17:$P17,AN$6) -> 1 | AO17: =COUNTIF($Q17:$W17,AO$6) -> 1 | AP17: =COUNTIF($Q17:$W17,AP$6) -> 1 | AQ17: =COUNTIF($X17:$AD17,AQ$6) -> 1 | AR17: =COUNTIF($X17:$AD17,AR$6) -> 1 | AS17: 전선영 | AT17: =COUNTIF(C17:AD17,"특*") -> 1 | AU17: =COUNTIF(C17:AD17,"경가") -> 0 | AV17: =COUNTIF(C17:AD17,"병*") -> 0 | AW17: =COUNTIF(C17:AD17,"공*") -> 0 | AX17: =COUNTIF(C17:AD17,"생*")+COUNTIF(C17:AD17,"산전")+COUNTIF(C17:AD17,"검진") -> 0 | AY17: =COUNTIF(C17:AD17,"법*") -> 0 | AZ17: =COUNTIF(C17:AD17,"*OFF*") -> 4 | BA17: =COUNTIF(C17:AD17,"VAC*")+COUNTIF(C17:AD17,"휴가") -> 2 | BB17: =COUNTIF(C17:AD17,"출산") -> 0 | BC17: =COUNTIF(C17:AD17,"*수면*") -> 0 | BD17: =COUNTIF(C17:AD17,"주") -> 4 | BE17: =SUM(AX17:BD17) -> 10 | BF17: =COUNTIF(J17:AD17,"N") -> 4 | BG17: =SUM(AU17:BD17) -> 10
A18: 이은지 | C18: OFF | D18: D | E18: D | F18: E | G18: E | H18: E | I18: 주 | J18: E | K18: E | L18: OFF | M18: E | N18: VAC | O18: D | P18: 주 | Q18: OFF | R18: 생휴 | S18: E | T18: N | U18: N | V18: N | W18: 주 | X18: off | Y18: D | Z18: D | AA18: E | AB18: VAC | AC18: D | AD18: 주 | AE18: =SUM(AT18:BD18) -> 11 | AF18: =COUNTIF(C18:AD18,"N") -> 3 | AK18: =COUNTIF($C18:$I18,AK$6) -> 1 | AL18: =COUNTIF($C18:$I18,AL$6&"*") -> 1 | AM18: =COUNTIF($J18:$P18,AM$6) -> 1 | AN18: =COUNTIF($J18:$P18,AN$6) -> 1 | AO18: =COUNTIF($Q18:$W18,AO$6) -> 1 | AP18: =COUNTIF($Q18:$W18,AP$6) -> 1 | AQ18: =COUNTIF($X18:$AD18,AQ$6) -> 1 | AR18: =COUNTIF($X18:$AD18,AR$6) -> 1 | AS18: 이은지 | AT18: =COUNTIF(C18:AD18,"특*") -> 0 | AU18: =COUNTIF(C18:AD18,"경가") -> 0 | AV18: =COUNTIF(C18:AD18,"병*") -> 0 | AW18: =COUNTIF(C18:AD18,"공*") -> 0 | AX18: =COUNTIF(C18:AD18,"생*")+COUNTIF(C18:AD18,"산전")+COUNTIF(C18:AD18,"검진") -> 1 | AY18: =COUNTIF(C18:AD18,"법*") -> 0 | AZ18: =COUNTIF(C18:AD18,"*OFF*") -> 4 | BA18: =COUNTIF(C18:AD18,"VAC*")+COUNTIF(C18:AD18,"휴가") -> 2 | BB18: =COUNTIF(C18:AD18,"출산") -> 0 | BC18: =COUNTIF(C18:AD18,"*수면*") -> 0 | BD18: =COUNTIF(C18:AD18,"주") -> 4 | BE18: =SUM(AX18:BD18) -> 11 | BF18: =COUNTIF(J18:AD18,"N") -> 3 | BG18: =SUM(AU18:BD18) -> 11
... A44: 손수연 | C44: 주 | D44: OFF | E44: 생휴 | F44: E | G44: E | H44: E | I44: E | J44: 주 | K44: E | L44: N | M44: OFF | N44: E | O44: E | P44: E | Q44: 주 | R44: OFF | S44: E | T44: E | U44: E | V44: N | W44: N | X44: 주 | Y44: OFF | Z44: VAC | AA44: VAC | AB44: N | AC44: N | AD44: N | AE44: =SUM(AT44:BD44) -> 11 | AF44: =COUNTIF(C44:AD44,"N") -> 6 | AK44: =COUNTIF($C44:$I44,AK$6) -> 1 | AL44: =COUNTIF($C44:$I44,AL$6&"*") -> 1 | AM44: =COUNTIF($J44:$P44,AM$6) -> 1 | AN44: =COUNTIF($J44:$P44,AN$6) -> 1 | AO44: =COUNTIF($Q44:$W44,AO$6) -> 1 | AP44: =COUNTIF($Q44:$W44,AP$6) -> 1 | AQ44: =COUNTIF($X44:$AD44,AQ$6) -> 1 | AR44: =COUNTIF($X44:$AD44,AR$6) -> 1 | AS44: 손수연 | AT44: =COUNTIF(C44:AD44,"특*") -> 0 | AU44: =COUNTIF(C44:AD44,"경가") -> 0 | AV44: =COUNTIF(C44:AD44,"병*") -> 0 | AW44: =COUNTIF(C44:AD44,"공*") -> 0 | AX44: =COUNTIF(C44:AD44,"생*")+COUNTIF(C44:AD44,"산전")+COUNTIF(C44:AD44,"검진") -> 1 | AY44: =COUNTIF(C44:AD44,"법*") -> 0 | AZ44: =COUNTIF(C44:AD44,"*OFF*") -> 4 | BA44: =COUNTIF(C44:AD44,"VAC*")+COUNTIF(C44:AD44,"휴가") -> 2 | BB44: =COUNTIF(C44:AD44,"출산") -> 0 | BC44: =COUNTIF(C44:AD44,"*수면*") -> 0 | BD44: =COUNTIF(C44:AD44,"주") -> 4 | BE44: =SUM(AX44:BD44) -> 11 | BF44: =COUNTIF(J44:AD44,"N") -> 6 | BG44: =SUM(AU44:BD44) -> 11
A45: 김현진 | AE45: =SUM(AT45:BD45) -> 0 | AF45: =COUNTIF(C45:AD45,"N") -> 0 | AK45: =COUNTIF($C45:$I45,AK$6) -> 0 | AL45: =COUNTIF($C45:$I45,AL$6&"*") -> 0 | AM45: =COUNTIF($J45:$P45,AM$6) -> 0 | AN45: =COUNTIF($J45:$P45,AN$6) -> 0 | AO45: =COUNTIF($Q45:$W45,AO$6) -> 0 | AP45: =COUNTIF($Q45:$W45,AP$6) -> 0 | AQ45: =COUNTIF($X45:$AD45,AQ$6) -> 0 | AR45: =COUNTIF($X45:$AD45,AR$6) -> 0 | AS45: 김현진 | AT45: =COUNTIF(C45:AD45,"특*") -> 0 | AU45: =COUNTIF(C45:AD45,"경가") -> 0 | AV45: =COUNTIF(C45:AD45,"병*") -> 0 | AW45: =COUNTIF(C45:AD45,"공*") -> 0 | AX45: =COUNTIF(C45:AD45,"생*")+COUNTIF(C45:AD45,"산전")+COUNTIF(C45:AD45,"검진") -> 0 | AY45: =COUNTIF(C45:AD45,"법*") -> 0 | AZ45: =COUNTIF(C45:AD45,"*OFF*") -> 0 | BA45: =COUNTIF(C45:AD45,"VAC*")+COUNTIF(C45:AD45,"휴가") -> 0 | BB45: =COUNTIF(C45:AD45,"출산") -> 0 | BC45: =COUNTIF(C45:AD45,"*수면*") -> 0 | BD45: =COUNTIF(C45:AD45,"주") -> 0 | BE45: =SUM(AX45:BD45) -> 0 | BF45: =COUNTIF(J45:AD45,"N") -> 0 | BG45: =SUM(AU45:BD45) -> 0
A46: 박병호 | AE46: =SUM(AT46:BD46) -> 0 | AF46: =COUNTIF(C46:AD46,"N") -> 0 | AK46: =COUNTIF($C46:$I46,AK$6) -> 0 | AL46: =COUNTIF($C46:$I46,AL$6&"*") -> 0 | AM46: =COUNTIF($J46:$P46,AM$6) -> 0 | AN46: =COUNTIF($J46:$P46,AN$6) -> 0 | AO46: =COUNTIF($Q46:$W46,AO$6) -> 0 | AP46: =COUNTIF($Q46:$W46,AP$6) -> 0 | AQ46: =COUNTIF($X46:$AD46,AQ$6) -> 0 | AR46: =COUNTIF($X46:$AD46,AR$6) -> 0 | AS46: 박병호 | AT46: =COUNTIF(C46:AD46,"특*") -> 0 | AU46: =COUNTIF(C46:AD46,"경가") -> 0 | AV46: =COUNTIF(C46:AD46,"병*") -> 0 | AW46: =COUNTIF(C46:AD46,"공*") -> 0 | AX46: =COUNTIF(C46:AD46,"생*")+COUNTIF(C46:AD46,"산전")+COUNTIF(C46:AD46,"검진") -> 0 | AY46: =COUNTIF(C46:AD46,"법*") -> 0 | AZ46: =COUNTIF(C46:AD46,"*OFF*") -> 0 | BA46: =COUNTIF(C46:AD46,"VAC*")+COUNTIF(C46:AD46,"휴가") -> 0 | BB46: =COUNTIF(C46:AD46,"출산") -> 0 | BC46: =COUNTIF(C46:AD46,"*수면*") -> 0 | BD46: =COUNTIF(C46:AD46,"주") -> 0 | BE46: =SUM(AX46:BD46) -> 0 | BF46: =COUNTIF(J46:AD46,"N") -> 0 | BG46: =SUM(AU46:BD46) -> 0
A47: 배수영 | AE47: =SUM(AT47:BD47) -> 0 | AF47: =COUNTIF(C47:AD47,"N") -> 0 | AK47: =COUNTIF($C47:$I47,AK$6) -> 0 | AL47: =COUNTIF($C47:$I47,AL$6&"*") -> 0 | AM47: =COUNTIF($J47:$P47,AM$6) -> 0 | AN47: =COUNTIF($J47:$P47,AN$6) -> 0 | AO47: =COUNTIF($Q47:$W47,AO$6) -> 0 | AP47: =COUNTIF($Q47:$W47,AP$6) -> 0 | AQ47: =COUNTIF($X47:$AD47,AQ$6) -> 0 | AR47: =COUNTIF($X47:$AD47,AR$6) -> 0 | AS47: 배수영 | AT47: =COUNTIF(C47:AD47,"특*") -> 0 | AU47: =COUNTIF(C47:AD47,"경가") -> 0 | AV47: =COUNTIF(C47:AD47,"병*") -> 0 | AW47: =COUNTIF(C47:AD47,"공*") -> 0 | AX47: =COUNTIF(C47:AD47,"생*")+COUNTIF(C47:AD47,"산전")+COUNTIF(C47:AD47,"검진") -> 0 | AY47: =COUNTIF(C47:AD47,"법*") -> 0 | AZ47: =COUNTIF(C47:AD47,"*OFF*") -> 0 | BA47: =COUNTIF(C47:AD47,"VAC*")+COUNTIF(C47:AD47,"휴가") -> 0 | BB47: =COUNTIF(C47:AD47,"출산") -> 0 | BC47: =COUNTIF(C47:AD47,"*수면*") -> 0 | BD47: =COUNTIF(C47:AD47,"주") -> 0 | BE47: =SUM(AX47:BD47) -> 0 | BF47: =COUNTIF(J47:AD47,"N") -> 0 | BG47: =SUM(AU47:BD47) -> 0
A48: 김현빈 | AE48: =SUM(AT48:BD48) -> 0 | AF48: =COUNTIF(C48:AD48,"N") -> 0 | AK48: =COUNTIF($C48:$I48,AK$6) -> 0 | AL48: =COUNTIF($C48:$I48,AL$6&"*") -> 0 | AM48: =COUNTIF($J48:$P48,AM$6) -> 0 | AN48: =COUNTIF($J48:$P48,AN$6) -> 0 | AO48: =COUNTIF($Q48:$W48,AO$6) -> 0 | AP48: =COUNTIF($Q48:$W48,AP$6) -> 0 | AQ48: =COUNTIF($X48:$AD48,AQ$6) -> 0 | AR48: =COUNTIF($X48:$AD48,AR$6) -> 0 | AS48: 김현빈 | AT48: =COUNTIF(C48:AD48,"특*") -> 0 | AU48: =COUNTIF(C48:AD48,"경가") -> 0 | AV48: =COUNTIF(C48:AD48,"병*") -> 0 | AW48: =COUNTIF(C48:AD48,"공*") -> 0 | AX48: =COUNTIF(C48:AD48,"생*")+COUNTIF(C48:AD48,"산전")+COUNTIF(C48:AD48,"검진") -> 0 | AY48: =COUNTIF(C48:AD48,"법*") -> 0 | AZ48: =COUNTIF(C48:AD48,"*OFF*") -> 0 | BA48: =COUNTIF(C48:AD48,"VAC*")+COUNTIF(C48:AD48,"휴가") -> 0 | BB48: =COUNTIF(C48:AD48,"출산") -> 0 | BC48: =COUNTIF(C48:AD48,"*수면*") -> 0 | BD48: =COUNTIF(C48:AD48,"주") -> 0 | BE48: =SUM(AX48:BD48) -> 0 | BF48: =COUNTIF(J48:AD48,"N") -> 0 | BG48: =SUM(AU48:BD48) -> 0
A50: D | C50: =COUNTIF(C$7:C$45,$A50) -> 7 | D50: =COUNTIF(D$7:D$45,$A50) -> 8 | E50: =COUNTIF(E$7:E$45,$A50) -> 8 | F50: =COUNTIF(F$7:F$45,$A50) -> 7 | G50: =COUNTIF(G$7:G$45,$A50) -> 8 | H50: =COUNTIF(H$7:H$45,$A50) -> 8 | I50: =COUNTIF(I$7:I$45,$A50) -> 7 | J50: =COUNTIF(J$7:J$45,$A50) -> 7 | ... AD50: =COUNTIF(AD$7:AD$45,$A50) -> 7
A51: E | C51: =COUNTIF(C$7:C$45,$A51) -> 8 | D51: =COUNTIF(D$7:D$45,$A51) -> 8 | E51: =COUNTIF(E$7:E$45,$A51) -> 8 | F51: =COUNTIF(F$7:F$45,$A51) -> 8 | G51: =COUNTIF(G$7:G$45,$A51) -> 8 | H51: =COUNTIF(H$7:H$45,$A51) -> 8 | I51: =COUNTIF(I$7:I$45,$A51) -> 8 | J51: =COUNTIF(J$7:J$45,$A51) -> 8 | ... AD51: =COUNTIF(AD$7:AD$45,$A51) -> 8
A52: N | C52: =COUNTIF(C$7:C$45,$A52) -> 7 | D52: =COUNTIF(D$7:D$45,$A52) -> 7 | E52: =COUNTIF(E$7:E$45,$A52) -> 7 | F52: =COUNTIF(F$7:F$45,$A52) -> 7 | G52: =COUNTIF(G$7:G$45,$A52) -> 7 | H52: =COUNTIF(H$7:H$45,$A52) -> 7 | I52: =COUNTIF(I$7:I$45,$A52) -> 7 | J52: =COUNTIF(J$7:J$45,$A52) -> 7 | ... AD52: =COUNTIF(AD$7:AD$45,$A52) -> 7
A53: 중 | C53: =COUNTIF(C$7:C$45,$A53) -> 0 | D53: =COUNTIF(D$7:D$45,$A53) -> 0 | E53: =COUNTIF(E$7:E$45,$A53) -> 0 | F53: =COUNTIF(F$7:F$45,$A53) -> 0 | G53: =COUNTIF(G$7:G$45,$A53) -> 0 | H53: =COUNTIF(H$7:H$45,$A53) -> 0 | I53: =COUNTIF(I$7:I$45,$A53) -> 0 | J53: =COUNTIF(J$7:J$45,$A53) -> 0 | ... AD53: =COUNTIF(AD$7:AD$45,$A53) -> 0
A54: 중2 | C54: =COUNTIF(C$7:C$45,$A54) -> 0 | D54: =COUNTIF(D$7:D$45,$A54) -> 1 | E54: =COUNTIF(E$7:E$45,$A54) -> 0 | F54: =COUNTIF(F$7:F$45,$A54) -> 0 | G54: =COUNTIF(G$7:G$45,$A54) -> 0 | H54: =COUNTIF(H$7:H$45,$A54) -> 0 | I54: =COUNTIF(I$7:I$45,$A54) -> 0 | J54: =COUNTIF(J$7:J$45,$A54) -> 0 | ... AD54: =COUNTIF(AD$7:AD$45,$A54) -> 0

Sheet 비교(변경불가)
A1: 근무표 변경시 파트장에게 확인받고 변경해주세요 공지된 후 변경된 근무표는 초록색으로 변경하겠습니다. 공지 된 이후에 근무표 변경은 지양해주시길 바랍니다.
J3: ='변경(260104_260131)'!J3:U3 -> 2026.01.04._26.01.31. | AB3: 간호사 38(파트장포함)
C5: ='변경(260104_260131)'!C5 -> 4 | D5: ='변경(260104_260131)'!D5 -> 5 | E5: ='변경(260104_260131)'!E5 -> 6 | F5: ='변경(260104_260131)'!F5 -> 7 | G5: ='변경(260104_260131)'!G5 -> 8 | H5: ='변경(260104_260131)'!H5 -> 9 | I5: ='변경(260104_260131)'!I5 -> 10 | J5: ='변경(260104_260131)'!J5 -> 11 | ... AD5: ='변경(260104_260131)'!AD5 -> 31 | AE5: 총 | AF5: 총 | AK5: 1 | AM5: 2 | AO5: 3 | AQ5: 4
B6: 비고 | C6: ='변경(260104_260131)'!C6 -> 일 | D6: ='변경(260104_260131)'!D6 -> 월 | E6: ='변경(260104_260131)'!E6 -> 화 | F6: ='변경(260104_260131)'!F6 -> 수 | G6: ='변경(260104_260131)'!G6 -> 목 | H6: ='변경(260104_260131)'!H6 -> 금 | I6: ='변경(260104_260131)'!I6 -> 토 | J6: ='변경(260104_260131)'!J6 -> 일 | ... AD6: ='변경(260104_260131)'!AD6 -> 토 | AE6: OFF | AF6: N | AK6: 주 | AL6: OFF | AM6: 주 | AN6: OFF | AO6: 주 | AP6: OFF | AQ6: 주 | AR6: OFF | AT6: 특휴 | AU6: 경가 | AV6: 병가 | AW6: 공 | AX6: 생휴 | AY6: 법휴 | AZ6: OFF | BA6: VAC | BB6: 수면 | BC6: 주휴 | BD6: OFF계 | BE6: N | BF6: 병가,OFF,공휴 포함 | BS6: 1
A7: 이경희 | C7: =IF(EXACT('변경(260104_260131)'!C7,'원번표(수정불가)'!C7)=$BS$9,"","변경") | D7: =IF(EXACT('변경(260104_260131)'!D7,'원번표(수정불가)'!D7)=$BS$9,"","변경") | E7: =IF(EXACT('변경(260104_260131)'!E7,'원번표(수정불가)'!E7)=$BS$9,"","변경") | F7: =IF(EXACT('변경(260104_260131)'!F7,'원번표(수정불가)'!F7)=$BS$9,"","변경") | G7: =IF(EXACT('변경(260104_260131)'!G7,'원번표(수정불가)'!G7)=$BS$9,"","변경") | H7: =IF(EXACT('변경(260104_260131)'!H7,'원번표(수정불가)'!H7)=$BS$9,"","변경") | I7: =IF(EXACT('변경(260104_260131)'!I7,'원번표(수정불가)'!I7)=$BS$9,"","변경") | J7: =IF(EXACT('변경(260104_260131)'!J7,'원번표(수정불가)'!J7)=$BS$9,"","변경") | ... AD7: =IF(EXACT('변경(260104_260131)'!AD7,'원번표(수정불가)'!AD7)=$BS$9,"","변경") | AE7: =SUM(AT7:BC7) -> 0 | AF7: =COUNTIF(C7:AD7,"N") -> 0 | AK7: =COUNTIF($C7:$I7,AK$6) -> 0 | AL7: =COUNTIF($C7:$I7,AL$6&"*") -> 0 | AM7: =COUNTIF($J7:$P7,AM$6) -> 0 | AN7: =COUNTIF($J7:$P7,AN$6) -> 0 | AO7: =COUNTIF($Q7:$W7,AO$6) -> 0 | AP7: =COUNTIF($Q7:$W7,AP$6) -> 0 | AQ7: =COUNTIF($X7:$AD7,AQ$6) -> 0 | AR7: =COUNTIF($X7:$AD7,AR$6) -> 0 | AS7: 이경희 | AT7: =COUNTIF(C7:AD7,"특*") -> 0 | AU7: =COUNTIF(C7:AD7,"경가") -> 0 | AV7: =COUNTIF(C7:AD7,"병*") -> 0 | AW7: =COUNTIF(C7:AD7,"공*") -> 0 | AX7: =COUNTIF(C7:AD7,"생*")+COUNTIF(C7:AD7,"산전")+COUNTIF(C7:AD7,"검진") -> 0 | AY7: =COUNTIF(C7:AD7,"법*") -> 0 | AZ7: =COUNTIF(C7:AD7,"*OFF*") -> 0 | BA7: =COUNTIF(C7:AD7,"VAC*")+COUNTIF(C7:AD7,"휴가") -> 0 | BB7: =COUNTIF(C7:AD7,"수면*") -> 0 | BC7: =COUNTIF(C7:AD7,"주") -> 0 | BD7: =SUM(AX7:BC7) -> 0 | BE7: =COUNTIF(J7:AD7,"N") -> 0 | BF7: =SUM(AU7:BC7) -> 0 | BS7: 1
A8: 오선영 | C8: =IF(EXACT('변경(260104_260131)'!C8,'원번표(수정불가)'!C8)=$BS$9,"","변경") | D8: =IF(EXACT('변경(260104_260131)'!D8,'원번표(수정불가)'!D8)=$BS$9,"","변경") | E8: =IF(EXACT('변경(260104_260131)'!E8,'원번표(수정불가)'!E8)=$BS$9,"","변경") | F8: =IF(EXACT('변경(260104_260131)'!F8,'원번표(수정불가)'!F8)=$BS$9,"","변경") | G8: =IF(EXACT('변경(260104_260131)'!G8,'원번표(수정불가)'!G8)=$BS$9,"","변경") | H8: =IF(EXACT('변경(260104_260131)'!H8,'원번표(수정불가)'!H8)=$BS$9,"","변경") | I8: =IF(EXACT('변경(260104_260131)'!I8,'원번표(수정불가)'!I8)=$BS$9,"","변경") | J8: =IF(EXACT('변경(260104_260131)'!J8,'원번표(수정불가)'!J8)=$BS$9,"","변경") | ... AD8: =IF(EXACT('변경(260104_260131)'!AD8,'원번표(수정불가)'!AD8)=$BS$9,"","변경") | AE8: =SUM(AT8:BC8) -> 0 | AF8: =COUNTIF(C8:AD8,"N") -> 0 | AK8: =COUNTIF($C8:$I8,AK$6) -> 0 | AL8: =COUNTIF($C8:$I8,AL$6&"*") -> 0 | AM8: =COUNTIF($J8:$P8,AM$6) -> 0 | AN8: =COUNTIF($J8:$P8,AN$6) -> 0 | AO8: =COUNTIF($Q8:$W8,AO$6) -> 0 | AP8: =COUNTIF($Q8:$W8,AP$6) -> 0 | AQ8: =COUNTIF($X8:$AD8,AQ$6) -> 0 | AR8: =COUNTIF($X8:$AD8,AR$6) -> 0 | AS8: 오선영 | AT8: =COUNTIF(C8:AD8,"특*") -> 0 | AU8: =COUNTIF(C8:AD8,"경가") -> 0 | AV8: =COUNTIF(C8:AD8,"병*") -> 0 | AW8: =COUNTIF(C8:AD8,"공*") -> 0 | AX8: =COUNTIF(C8:AD8,"생*")+COUNTIF(C8:AD8,"산전")+COUNTIF(C8:AD8,"검진") -> 0 | AY8: =COUNTIF(C8:AD8,"법*") -> 0 | AZ8: =COUNTIF(C8:AD8,"*OFF*") -> 0 | BA8: =COUNTIF(C8:AD8,"VAC*")+COUNTIF(C8:AD8,"휴가") -> 0 | BB8: =COUNTIF(C8:AD8,"수면*") -> 0 | BC8: =COUNTIF(C8:AD8,"주") -> 0 | BD8: =SUM(AX8:BC8) -> 0 | BE8: =COUNTIF(J8:AD8,"N") -> 0 | BF8: =SUM(AU8:BC8) -> 0 | BS8: 2
A9: 우영미 | C9: =IF(EXACT('변경(260104_260131)'!C9,'원번표(수정불가)'!C9)=$BS$9,"","변경") | D9: =IF(EXACT('변경(260104_260131)'!D9,'원번표(수정불가)'!D9)=$BS$9,"","변경") | E9: =IF(EXACT('변경(260104_260131)'!E9,'원번표(수정불가)'!E9)=$BS$9,"","변경") | F9: =IF(EXACT('변경(260104_260131)'!F9,'원번표(수정불가)'!F9)=$BS$9,"","변경") | G9: =IF(EXACT('변경(260104_260131)'!G9,'원번표(수정불가)'!G9)=$BS$9,"","변경") | H9: =IF(EXACT('변경(260104_260131)'!H9,'원번표(수정불가)'!H9)=$BS$9,"","변경") | I9: =IF(EXACT('변경(260104_260131)'!I9,'원번표(수정불가)'!I9)=$BS$9,"","변경") -> 변경 | J9: =IF(EXACT('변경(260104_260131)'!J9,'원번표(수정불가)'!J9)=$BS$9,"","변경") | ... AD9: =IF(EXACT('변경(260104_260131)'!AD9,'원번표(수정불가)'!AD9)=$BS$9,"","변경") -> 변경 | AE9: =SUM(AT9:BC9) -> 0 | AF9: =COUNTIF(C9:AD9,"N") -> 0 | AK9: =COUNTIF($C9:$I9,AK$6) -> 0 | AL9: =COUNTIF($C9:$I9,AL$6&"*") -> 0 | AM9: =COUNTIF($J9:$P9,AM$6) -> 0 | AN9: =COUNTIF($J9:$P9,AN$6) -> 0 | AO9: =COUNTIF($Q9:$W9,AO$6) -> 0 | AP9: =COUNTIF($Q9:$W9,AP$6) -> 0 | AQ9: =COUNTIF($X9:$AD9,AQ$6) -> 0 | AR9: =COUNTIF($X9:$AD9,AR$6) -> 0 | AS9: 우영미 | AT9: =COUNTIF(C9:AD9,"특*") -> 0 | AU9: =COUNTIF(C9:AD9,"경가") -> 0 | AV9: =COUNTIF(C9:AD9,"병*") -> 0 | AW9: =COUNTIF(C9:AD9,"공*") -> 0 | AX9: =COUNTIF(C9:AD9,"생*")+COUNTIF(C9:AD9,"산전")+COUNTIF(C9:AD9,"검진") -> 0 | AY9: =COUNTIF(C9:AD9,"법*") -> 0 | AZ9: =COUNTIF(C9:AD9,"*OFF*") -> 0 | BA9: =COUNTIF(C9:AD9,"VAC*")+COUNTIF(C9:AD9,"휴가") -> 0 | BB9: =COUNTIF(C9:AD9,"수면*") -> 0 | BC9: =COUNTIF(C9:AD9,"주") -> 0 | BD9: =SUM(AX9:BC9) -> 0 | BE9: =COUNTIF(J9:AD9,"N") -> 0 | BF9: =SUM(AU9:BC9) -> 0 | BS9: =EXACT(BS6,BS7) -> TRUE
A10: 전상배 | C10: =IF(EXACT('변경(260104_260131)'!C10,'원번표(수정불가)'!C10)=$BS$9,"","변경") | D10: =IF(EXACT('변경(260104_260131)'!D10,'원번표(수정불가)'!D10)=$BS$9,"","변경") | E10: =IF(EXACT('변경(260104_260131)'!E10,'원번표(수정불가)'!E10)=$BS$9,"","변경") | F10: =IF(EXACT('변경(260104_260131)'!F10,'원번표(수정불가)'!F10)=$BS$9,"","변경") | G10: =IF(EXACT('변경(260104_260131)'!G10,'원번표(수정불가)'!G10)=$BS$9,"","변경") | H10: =IF(EXACT('변경(260104_260131)'!H10,'원번표(수정불가)'!H10)=$BS$9,"","변경") | I10: =IF(EXACT('변경(260104_260131)'!I10,'원번표(수정불가)'!I10)=$BS$9,"","변경") | J10: =IF(EXACT('변경(260104_260131)'!J10,'원번표(수정불가)'!J10)=$BS$9,"","변경") | ... AD10: =IF(EXACT('변경(260104_260131)'!AD10,'원번표(수정불가)'!AD10)=$BS$9,"","변경") -> 변경 | AE10: =SUM(AT10:BC10) -> 0 | AF10: =COUNTIF(C10:AD10,"N") -> 0 | AK10: =COUNTIF($C10:$I10,AK$6) -> 0 | AL10: =COUNTIF($C10:$I10,AL$6&"*") -> 0 | AM10: =COUNTIF($J10:$P10,AM$6) -> 0 | AN10: =COUNTIF($J10:$P10,AN$6) -> 0 | AO10: =COUNTIF($Q10:$W10,AO$6) -> 0 | AP10: =COUNTIF($Q10:$W10,AP$6) -> 0 | AQ10: =COUNTIF($X10:$AD10,AQ$6) -> 0 | AR10: =COUNTIF($X10:$AD10,AR$6) -> 0 | AS10: 전상배 | AT10: =COUNTIF(C10:AD10,"특*") -> 0 | AU10: =COUNTIF(C10:AD10,"경가") -> 0 | AV10: =COUNTIF(C10:AD10,"병*") -> 0 | AW10: =COUNTIF(C10:AD10,"공*") -> 0 | AX10: =COUNTIF(C10:AD10,"생*")+COUNTIF(C10:AD10,"산전")+COUNTIF(C10:AD10,"검진") -> 0 | AY10: =COUNTIF(C10:AD10,"법*") -> 0 | AZ10: =COUNTIF(C10:AD10,"*OFF*") -> 0 | BA10: =COUNTIF(C10:AD10,"VAC*")+COUNTIF(C10:AD10,"휴가") -> 0 | BB10: =COUNTIF(C10:AD10,"수면*") -> 0 | BC10: =COUNTIF(C10:AD10,"주") -> 0 | BD10: =SUM(AX10:BC10) -> 0 | BE10: =COUNTIF(J10:AD10,"N") -> 0 | BF10: =SUM(AU10:BC10) -> 0 | BS10: =EXACT(BS7,BS8) -> FALSE
A11: 안일심 | C11: =IF(EXACT('변경(260104_260131)'!C11,'원번표(수정불가)'!C11)=$BS$9,"","변경") | D11: =IF(EXACT('변경(260104_260131)'!D11,'원번표(수정불가)'!D11)=$BS$9,"","변경") | E11: =IF(EXACT('변경(260104_260131)'!E11,'원번표(수정불가)'!E11)=$BS$9,"","변경") | F11: =IF(EXACT('변경(260104_260131)'!F11,'원번표(수정불가)'!F11)=$BS$9,"","변경") | G11: =IF(EXACT('변경(260104_260131)'!G11,'원번표(수정불가)'!G11)=$BS$9,"","변경") | H11: =IF(EXACT('변경(260104_260131)'!H11,'원번표(수정불가)'!H11)=$BS$9,"","변경") | I11: =IF(EXACT('변경(260104_260131)'!I11,'원번표(수정불가)'!I11)=$BS$9,"","변경") | J11: =IF(EXACT('변경(260104_260131)'!J11,'원번표(수정불가)'!J11)=$BS$9,"","변경") | ... AD11: =IF(EXACT('변경(260104_260131)'!AD11,'원번표(수정불가)'!AD11)=$BS$9,"","변경") | AE11: =SUM(AT11:BC11) -> 0 | AF11: =COUNTIF(C11:AD11,"N") -> 0 | AK11: =COUNTIF($C11:$I11,AK$6) -> 0 | AL11: =COUNTIF($C11:$I11,AL$6&"*") -> 0 | AM11: =COUNTIF($J11:$P11,AM$6) -> 0 | AN11: =COUNTIF($J11:$P11,AN$6) -> 0 | AO11: =COUNTIF($Q11:$W11,AO$6) -> 0 | AP11: =COUNTIF($Q11:$W11,AP$6) -> 0 | AQ11: =COUNTIF($X11:$AD11,AQ$6) -> 0 | AR11: =COUNTIF($X11:$AD11,AR$6) -> 0 | AS11: 안일심 | AT11: =COUNTIF(C11:AD11,"특*") -> 0 | AU11: =COUNTIF(C11:AD11,"경가") -> 0 | AV11: =COUNTIF(C11:AD11,"병*") -> 0 | AW11: =COUNTIF(C11:AD11,"공*") -> 0 | AX11: =COUNTIF(C11:AD11,"생*")+COUNTIF(C11:AD11,"산전")+COUNTIF(C11:AD11,"검진") -> 0 | AY11: =COUNTIF(C11:AD11,"법*") -> 0 | AZ11: =COUNTIF(C11:AD11,"*OFF*") -> 0 | BA11: =COUNTIF(C11:AD11,"VAC*")+COUNTIF(C11:AD11,"휴가") -> 0 | BB11: =COUNTIF(C11:AD11,"수면*") -> 0 | BC11: =COUNTIF(C11:AD11,"주") -> 0 | BD11: =SUM(AX11:BC11) -> 0 | BE11: =COUNTIF(J11:AD11,"N") -> 0 | BF11: =SUM(AU11:BC11) -> 0
A12: 조은애 | C12: =IF(EXACT('변경(260104_260131)'!C12,'원번표(수정불가)'!C12)=$BS$9,"","변경") | D12: =IF(EXACT('변경(260104_260131)'!D12,'원번표(수정불가)'!D12)=$BS$9,"","변경") | E12: =IF(EXACT('변경(260104_260131)'!E12,'원번표(수정불가)'!E12)=$BS$9,"","변경") | F12: =IF(EXACT('변경(260104_260131)'!F12,'원번표(수정불가)'!F12)=$BS$9,"","변경") | G12: =IF(EXACT('변경(260104_260131)'!G12,'원번표(수정불가)'!G12)=$BS$9,"","변경") | H12: =IF(EXACT('변경(260104_260131)'!H12,'원번표(수정불가)'!H12)=$BS$9,"","변경") | I12: =IF(EXACT('변경(260104_260131)'!I12,'원번표(수정불가)'!I12)=$BS$9,"","변경") | J12: =IF(EXACT('변경(260104_260131)'!J12,'원번표(수정불가)'!J12)=$BS$9,"","변경") | ... AD12: =IF(EXACT('변경(260104_260131)'!AD12,'원번표(수정불가)'!AD12)=$BS$9,"","변경") | AE12: =SUM(AT12:BC12) -> 0 | AF12: =COUNTIF(C12:AD12,"N") -> 0 | AK12: =COUNTIF($C12:$I12,AK$6) -> 0 | AL12: =COUNTIF($C12:$I12,AL$6&"*") -> 0 | AM12: =COUNTIF($J12:$P12,AM$6) -> 0 | AN12: =COUNTIF($J12:$P12,AN$6) -> 0 | AO12: =COUNTIF($Q12:$W12,AO$6) -> 0 | AP12: =COUNTIF($Q12:$W12,AP$6) -> 0 | AQ12: =COUNTIF($X12:$AD12,AQ$6) -> 0 | AR12: =COUNTIF($X12:$AD12,AR$6) -> 0 | AS12: 조은애 | AT12: =COUNTIF(C12:AD12,"특*") -> 0 | AU12: =COUNTIF(C12:AD12,"경가") -> 0 | AV12: =COUNTIF(C12:AD12,"병*") -> 0 | AW12: =COUNTIF(C12:AD12,"공*") -> 0 | AX12: =COUNTIF(C12:AD12,"생*")+COUNTIF(C12:AD12,"산전")+COUNTIF(C12:AD12,"검진") -> 0 | AY12: =COUNTIF(C12:AD12,"법*") -> 0 | AZ12: =COUNTIF(C12:AD12,"*OFF*") -> 0 | BA12: =COUNTIF(C12:AD12,"VAC*")+COUNTIF(C12:AD12,"휴가") -> 0 | BB12: =COUNTIF(C12:AD12,"수면*") -> 0 | BC12: =COUNTIF(C12:AD12,"주") -> 0 | BD12: =SUM(AX12:BC12) -> 0 | BE12: =COUNTIF(J12:AD12,"N") -> 0 | BF12: =SUM(AU12:BC12) -> 0
A13: 우혜린 | C13: =IF(EXACT('변경(260104_260131)'!C13,'원번표(수정불가)'!C13)=$BS$9,"","변경") | D13: =IF(EXACT('변경(260104_260131)'!D13,'원번표(수정불가)'!D13)=$BS$9,"","변경") | E13: =IF(EXACT('변경(260104_260131)'!E13,'원번표(수정불가)'!E13)=$BS$9,"","변경") | F13: =IF(EXACT('변경(260104_260131)'!F13,'원번표(수정불가)'!F13)=$BS$9,"","변경") | G13: =IF(EXACT('변경(260104_260131)'!G13,'원번표(수정불가)'!G13)=$BS$9,"","변경") | H13: =IF(EXACT('변경(260104_260131)'!H13,'원번표(수정불가)'!H13)=$BS$9,"","변경") | I13: =IF(EXACT('변경(260104_260131)'!I13,'원번표(수정불가)'!I13)=$BS$9,"","변경") | J13: =IF(EXACT('변경(260104_260131)'!J13,'원번표(수정불가)'!J13)=$BS$9,"","변경") | ... AD13: =IF(EXACT('변경(260104_260131)'!AD13,'원번표(수정불가)'!AD13)=$BS$9,"","변경") | AE13: =SUM(AT13:BC13) -> 0 | AF13: =COUNTIF(C13:AD13,"N") -> 0 | AK13: =COUNTIF($C13:$I13,AK$6) -> 0 | AL13: =COUNTIF($C13:$I13,AL$6&"*") -> 0 | AM13: =COUNTIF($J13:$P13,AM$6) -> 0 | AN13: =COUNTIF($J13:$P13,AN$6) -> 0 | AO13: =COUNTIF($Q13:$W13,AO$6) -> 0 | AP13: =COUNTIF($Q13:$W13,AP$6) -> 0 | AQ13: =COUNTIF($X13:$AD13,AQ$6) -> 0 | AR13: =COUNTIF($X13:$AD13,AR$6) -> 0 | AS13: 우혜린 | AT13: =COUNTIF(C13:AD13,"특*") -> 0 | AU13: =COUNTIF(C13:AD13,"경가") -> 0 | AV13: =COUNTIF(C13:AD13,"병*") -> 0 | AW13: =COUNTIF(C13:AD13,"공*") -> 0 | AX13: =COUNTIF(C13:AD13,"생*")+COUNTIF(C13:AD13,"산전")+COUNTIF(C13:AD13,"검진") -> 0 | AY13: =COUNTIF(C13:AD13,"법*") -> 0 | AZ13: =COUNTIF(C13:AD13,"*OFF*") -> 0 | BA13: =COUNTIF(C13:AD13,"VAC*")+COUNTIF(C13:AD13,"휴가") -> 0 | BB13: =COUNTIF(C13:AD13,"수면*") -> 0 | BC13: =COUNTIF(C13:AD13,"주") -> 0 | BD13: =SUM(AX13:BC13) -> 0 | BE13: =COUNTIF(J13:AD13,"N") -> 0 | BF13: =SUM(AU13:BC13) -> 0
A14: 유지연 | C14: =IF(EXACT('변경(260104_260131)'!C14,'원번표(수정불가)'!C14)=$BS$9,"","변경") | D14: =IF(EXACT('변경(260104_260131)'!D14,'원번표(수정불가)'!D14)=$BS$9,"","변경") | E14: =IF(EXACT('변경(260104_260131)'!E14,'원번표(수정불가)'!E14)=$BS$9,"","변경") | F14: =IF(EXACT('변경(260104_260131)'!F14,'원번표(수정불가)'!F14)=$BS$9,"","변경") | G14: =IF(EXACT('변경(260104_260131)'!G14,'원번표(수정불가)'!G14)=$BS$9,"","변경") | H14: =IF(EXACT('변경(260104_260131)'!H14,'원번표(수정불가)'!H14)=$BS$9,"","변경") | I14: =IF(EXACT('변경(260104_260131)'!I14,'원번표(수정불가)'!I14)=$BS$9,"","변경") | J14: =IF(EXACT('변경(260104_260131)'!J14,'원번표(수정불가)'!J14)=$BS$9,"","변경") | ... AD14: =IF(EXACT('변경(260104_260131)'!AD14,'원번표(수정불가)'!AD14)=$BS$9,"","변경") | AE14: =SUM(AT14:BC14) -> 0 | AF14: =COUNTIF(C14:AD14,"N") -> 0 | AK14: =COUNTIF($C14:$I14,AK$6) -> 0 | AL14: =COUNTIF($C14:$I14,AL$6&"*") -> 0 | AM14: =COUNTIF($J14:$P14,AM$6) -> 0 | AN14: =COUNTIF($J14:$P14,AN$6) -> 0 | AO14: =COUNTIF($Q14:$W14,AO$6) -> 0 | AP14: =COUNTIF($Q14:$W14,AP$6) -> 0 | AQ14: =COUNTIF($X14:$AD14,AQ$6) -> 0 | AR14: =COUNTIF($X14:$AD14,AR$6) -> 0 | AS14: 유지연 | AT14: =COUNTIF(C14:AD14,"특*") -> 0 | AU14: =COUNTIF(C14:AD14,"경가") -> 0 | AV14: =COUNTIF(C14:AD14,"병*") -> 0 | AW14: =COUNTIF(C14:AD14,"공*") -> 0 | AX14: =COUNTIF(C14:AD14,"생*")+COUNTIF(C14:AD14,"산전")+COUNTIF(C14:AD14,"검진") -> 0 | AY14: =COUNTIF(C14:AD14,"법*") -> 0 | AZ14: =COUNTIF(C14:AD14,"*OFF*") -> 0 | BA14: =COUNTIF(C14:AD14,"VAC*")+COUNTIF(C14:AD14,"휴가") -> 0 | BB14: =COUNTIF(C14:AD14,"수면*") -> 0 | BC14: =COUNTIF(C14:AD14,"주") -> 0 | BD14: =SUM(AX14:BC14) -> 0 | BE14: =COUNTIF(J14:AD14,"N") -> 0 | BF14: =SUM(AU14:BC14) -> 0
